Workbook

Sheet Excluded
A1: no | B1: remove | C1: opsin name | D1: other name | E1: source (species) | F1: Rhodopsin Type (Microbial) | G1: class (function) | H1: molecular_function | I1: PDB ID | J1: method | K1: resolution | L1: reference | M1: sequence | N1: pdb_id | O1: structure_sequence | P1: uniprot_id | Q1: length | R1: seq | S1: end | T1: start | U1: name | V1: protein | W1: protein_id | X1: experimentally_determined | Y1: display_name | Z1: short_name | AA1: molecular_function_normalized | AB1: full_protein
A2: 2 | B2: include | C2: CrChR1 | E2: Chlamydomonas reinhardtii | F2: Eukaryota | G2: cation channel | H2: non-selective cation channel | M2: MSRRPWLLALALAVALAAGSAGASTGSDATVPVATQDGPDYVFHRAHERMLFQTSYTLENNGSVICIPNNGQCFCLAWLKSNGTNAEKLAANILQWITFALSALCLMFYGYQTWKSTCGWEEIYVATIEMIKFIIEYFHEFDEPAVIYSSNGNKTVWLRYAEWLLTCPVILIHLSNLTGLANDYNKRTMGLLVSDIGTIVWGTTAALSKGYVRVIFFLMGLCYGIYTFFNAAKVYIEAYHTVPKGICRDLVRYLAWLYFCSWAMFPVLFLLGPEGFGHINQFNSAIAHAILDLASKNAWSMMGHFLRVKIHEHILLYGDIRKKQKVNVAGQEMEVETMVHEEDDETQKVPTAKYANRDSFIIMRDRLKEKGFETRASLDGDPNGDAEANAAAGGKPGMEMGKMTGMGMGMGAGMGMATIDSGRVILAVPDISMVDFFREQFARLPVPYELVPALGAENTLQLVQQAQSLGGCDFVLMHPEFLRDRSPTGLLPRLKMGGQRAAAFGWAAIGPMRDLIEGSGVDGWLEGPSFGAGINQQALVALINRMQQAKKMGMMGGMGMGMGGGMGMGMGMGMGMAPSMNAGMTGGMGGASMGGAVMGMGMGMQPMQQAMPAMSPMMTQQPSMMSQPSAMSAGGAMQAMGGVMPSPAPGGRVGTNPLFGSAPSPLSSQPGISPGMATPPAATAAPAAGGSEAEMLQQLMSEINRLKNELGE | N2: 3UG9 | O2: RMLFQTSYTLENNGSVICIPNNGQCFCLAWLKSNGTNAEKLAANILQWITFALSALCLMFYCGWEEIYVATIEMIKFIIEYFHEFDEPAVIYSSNGNKTVWLRYAEWLLTCPVILIHLSNLTGLANDYNKRTMGLLVSDIGTIVWGTTAALSKGYVRVIFFLMGLCYGIYTFFNAAKVYIEAYHTVPKGRCRQVVTGMAWLFFVSWGMFPILFILGPEGFGVLSVYGSTVGHTIIDLMSKNCWGLLGHYLRVLIHEHILIHGDIRKTTKLIEVETLVEDE | P2: Q93WP2,Q8RUT8 | Q2: 280.0 | R2: RMLFQTSYTLENNGSVICIPNNGQCFCLAWLKSNGTNAEKLAANILQWITFALSALCLMFYCGWEEIYVATIEMIKFIIEYFHEFDEPAVIYSSNGNKTVWLRYAEWLLTCPVILIHLSNLTGLANDYNKRTMGLLVSDIGTIVWGTTAALSKGYVRVIFFLMGLCYGIYTFFNAAKVYIEAYHTVPKGRCRQVVTGMAWLFFVSWGMFPILFILGPEGFGVLSVYGSTVGHTIIDLMSKNCWGLLGHYLRVLIHEHILIHGDIRKTTKLIEVETLVEDE | U2: Chlamydomonas reinhardtii Channelrhodopsin-1 | V2: Chlamydomonas_reinhardtii_Channelrhodopsin_1 | W2: O5537c97da | X2: TRUE | Y2: CrChR1 | Z2: CrChR1 | AA2: Cation channel | AB2: Chlamydomonas_reinhardtii_Channelrhodopsin_1_Chlamydomonas reinhardtii
A3: 4 | B3: include | C3: FR | E3: Fulvimarina pelagi | F3: Bacteria | G3: inward chloride pump | H3: inward chloride pump | M3: MQDTELFADQLGNIENLVSLTVGQYTMGSLILMVSYGAHFAFVLYFLMTSLQLAPRYRIVPIMSAIVMVSAGLSLLREFNAWEQSYEFVEGMYQPLAENSTFTNAYRYGNWTITVPILLTQLPLAFGLLRPELHVRAARMCIPALLMIWTGLVGQFGETGNYLRLNVWGVISTIFFVWLIIEVRGVISRAIAMGPAELAAWPKNIWWFFLAFWGLYPIAYALPQLGHTGDIVVIRQLLYSIADVFSKLVYGIILSRYVLRRSALEGYKPAIEALSRTPVDLSMSKNGGAGYGDGDR | Q3: 296.0 | R3: MQDTELFADQLGNIENLVSLTVGQYTMGSLILMVSYGAHFAFVLYFLMTSLQLAPRYRIVPIMSAIVMVSAGLSLLREFNAWEQSYEFVEGMYQPLAENSTFTNAYRYGNWTITVPILLTQLPLAFGLLRPELHVRAARMCIPALLMIWTGLVGQFGETGNYLRLNVWGVISTIFFVWLIIEVRGVISRAIAMGPAELAAWPKNIWWFFLAFWGLYPIAYALPQLGHTGDIVVIRQLLYSIADVFSKLVYGIILSRYVLRRSALEGYKPAIEALSRTPVDLSMSKNGGAGYGDGDR | U3: Fulvimarina pelagi Chloride pump | V3: Fulvimarina_pelagi_Chloride_pump | W3: Of45b61cb1 | X3: FALSE | Y3: FR | Z3: FR | AA3: Chloride pump | AB3: Fulvimarina_pelagi_Chloride_pump_Fulvimarina pelagi
A4: 5 | B4: include | C4: GPR | E4: Marine proteobacteria (labeled 'Green') | F4: Bacteria | G4: outward proton pump | H4: outward proton pump | M4: MKLLLILGSVIALPTFAAGGGDLDASDYTGVSFWLVTAALLASTVFFFVERDRVSAKWKTSLTVSGLVTGIAFWHYMYMRGVWIETGDSPTVFRYIDWLLTVPLLICEFYLILAAATNVAGSLFKKLLVGSLVMLVFGYMGEAGIMAAWPAFIIGCLAWVYMIYELWAGEGKSACNTASPAVQSAYNTMMYIIIFGWAIYPVGYFTGYLMGDGGSALNLNLIYNLADFVNKILFGLIIWNVAVKESSNA | N4: 2L6X | O4: MGGGDLDASDYTGVSFWLVTAALLASTVFFFVERDRVSAKWKTSLTVSGLVTGIAFWHYMYMRGVWIETGDSPTVFRYIDWLLTVPLLICEFYLILAAATNVAGSLFKKLLVGSLVMLVFGYMGEAGIMAAWPAFIIGCLAWVYMIYELWAGEGKSACNTASPAVQSAYNTMMYIIIFGWAIYPVGYFTGYLMGDGGSALNLNLIYNLADFVNKILFGLIIWNVAVKESSNAPGG | P4: Q9F7P4 | Q4: 235.0 | R4: MGGGDLDASDYTGVSFWLVTAALLASTVFFFVERDRVSAKWKTSLTVSGLVTGIAFWHYMYMRGVWIETGDSPTVFRYIDWLLTVPLLICEFYLILAAATNVAGSLFKKLLVGSLVMLVFGYMGEAGIMAAWPAFIIGCLAWVYMIYELWAGEGKSACNTASPAVQSAYNTMMYIIIFGWAIYPVGYFTGYLMGDGGSALNLNLIYNLADFVNKILFGLIIWNVAVKESSNAPGG | U4: Green Proteorhodopsin | V4: Green_Proteorhodopsin | W4: O7b6459cd7 | X4: TRUE | Y4: GPR | Z4: GPR | AA4: Proton pump | AB4: Green_Proteorhodopsin_Marine proteobacteria (labeled 'Green')
A5: 6 | B5: include | C5: GtACR2 | E5: Guillardia theta | F5: Eukaryota | G5: anion channel | H5: non-selective anion channel | M5: MASQVVYGEWASTHTECYNMSRIDSTFVSLLQLVWAVVSGCQTIFMISRAPKVPWESVYLPFVESITYALASTGNGTLQMRDGRFFPWSRMASWLCTCPIMLGQISNMALVKYKSIPLNPIAQAASIIRVVMGITATISPAEYMKWLFFFFGATCLVFEYSVVFTIFQVGLYGFESVGTPLAQKVVVRIKMLRLIFFIAWTMFPIVWLISPTGVCVIHENVSAILYLLADGLCKNTYGVILWSTAWGVLEGKWDPACLPGQEKPEADDPFGLNHEKNAPPNDEVNIRMFGR | Q5: 291.0 | R5: MASQVVYGEWASTHTECYNMSRIDSTFVSLLQLVWAVVSGCQTIFMISRAPKVPWESVYLPFVESITYALASTGNGTLQMRDGRFFPWSRMASWLCTCPIMLGQISNMALVKYKSIPLNPIAQAASIIRVVMGITATISPAEYMKWLFFFFGATCLVFEYSVVFTIFQVGLYGFESVGTPLAQKVVVRIKMLRLIFFIAWTMFPIVWLISPTGVCVIHENVSAILYLLADGLCKNTYGVILWSTAWGVLEGKWDPACLPGQEKPEADDPFGLNHEKNAPPNDEVNIRMFGR | U5: Guillardia theta Anion Channelrhodopsin-2 | V5: Guillardia_theta_Anion_Channelrhodopsin_2 | W5: O9d96fda5e | X5: FALSE | Y5: GtACR2 | Z5: GtACR2 | AA5: Anion channel | AB5: Guillardia_theta_Anion_Channelrhodopsin_2_Guillardia theta
A6: 9 | B6: include | C6: HmHR | E6: Haloarcula marismortui | F6: Archaea | G6: inward chloride pump | H6: inward chloride pump | M6: MTAASTTATTVLQATQSDVLQEIQSNFLLNSSIWVNIALAGVVILLFVAMGRDLESPRAKLIWVATMLVPLVSISSYAGLASGLTVGFLQMPPGHALAGQEVLSPWGRYLTWTFSTPMILLALGLLADTDIASLFTAITMDIGMCVTGLAAALITSSHLLRWVFYGISCAFFVAVLYVLLVQWPADAEAAGTSEIFGTLKILTVVLWLGYPILWALGSEGVALLSVGVTSWGYSGLDILAKYVFAFLLLRWVAANEGTVSGSGMGIGSGGATPADD | Q6: 276.0 | R6: MTAASTTATTVLQATQSDVLQEIQSNFLLNSSIWVNIALAGVVILLFVAMGRDLESPRAKLIWVATMLVPLVSISSYAGLASGLTVGFLQMPPGHALAGQEVLSPWGRYLTWTFSTPMILLALGLLADTDIASLFTAITMDIGMCVTGLAAALITSSHLLRWVFYGISCAFFVAVLYVLLVQWPADAEAAGTSEIFGTLKILTVVLWLGYPILWALGSEGVALLSVGVTSWGYSGLDILAKYVFAFLLLRWVAANEGTVSGSGMGIGSGGATPADD | U6: Haloarcula marismortui Halorhodopsin | V6: Haloarcula_marismortui_Halorhodopsin | W6: O017a1ade5 | X6: FALSE | Y6: HmHR | Z6: HmHR | AA6: Chloride pump | AB6: Haloarcula_marismortui_Halorhodopsin_Haloarcula marismortui
A7: 10 | B7: include | C7: HmSRI | E7: Haloarcula marismortui | F7: Archaea | G7: regulation of transducer | H7: regulation of transducer | M7: MDAVSVVYGITAAGFAVGVAIVGFLYASLEGSDERPILAALALIPGVAGISYVAMVFGIGTVTIGETTLVGFRYLDWVVTTPLLVGFIGYTAGASRRAIFGVMAADALMILAGVGAVVAAGTLKWALFGVSAVFHISLFAYLYLIFPRSVPDDPQRIGLFSLLKNHVGLLWIAYPLVWLAGPEGLGFATYVGVSITYAFLDLLAKVPYVYFFYARRQVFATKLLRDSGDTTVTPAD | Q7: 236.0 | R7: MDAVSVVYGITAAGFAVGVAIVGFLYASLEGSDERPILAALALIPGVAGISYVAMVFGIGTVTIGETTLVGFRYLDWVVTTPLLVGFIGYTAGASRRAIFGVMAADALMILAGVGAVVAAGTLKWALFGVSAVFHISLFAYLYLIFPRSVPDDPQRIGLFSLLKNHVGLLWIAYPLVWLAGPEGLGFATYVGVSITYAFLDLLAKVPYVYFFYARRQVFATKLLRDSGDTTVTPAD | U7: Haloarcula marismortui Sensory Rhodopsin I | V7: Haloarcula_marismortui_Sensory_Rhodopsin_I | W7: O132494edf | X7: FALSE | Y7: HmSRI | Z7: HmSRI | AA7: Phototaxis | AB7: Haloarcula_marismortui_Sensory_Rhodopsin_I_Haloarcula marismortui
A8: 11 | B8: include | C8: HmSRII | E8: Haloarcula marismortui | F8: Archaea | G8: regulation of transducer | H8: regulation of transducer | M8: MATITTWFTLGLLGELLGTAVLAYGYTLVPEETRKRYLLLIAIPGIAIVAYALMALGFGSIQSEGHAVYVVRYVDWLLTTPLNVWFLALLAGASREDTVKLVVLQALTIVFGFAGAVTPSPVSYALFAVGGALFGGVIYLLYRNIAVAAKSTLSDIEVSLYRTLRNFVVVLWLVYPVVWLLGAAGVGLMDVETATLVVVYLDVVTKVGFGVIALLAMIDLGSAGETAEEPTAVAGD | Q8: 236.0 | R8: MATITTWFTLGLLGELLGTAVLAYGYTLVPEETRKRYLLLIAIPGIAIVAYALMALGFGSIQSEGHAVYVVRYVDWLLTTPLNVWFLALLAGASREDTVKLVVLQALTIVFGFAGAVTPSPVSYALFAVGGALFGGVIYLLYRNIAVAAKSTLSDIEVSLYRTLRNFVVVLWLVYPVVWLLGAAGVGLMDVETATLVVVYLDVVTKVGFGVIALLAMIDLGSAGETAEEPTAVAGD | U8: Haloarcula marismortui Sensory Rhodopsin II | V8: Haloarcula_marismortui_Sensory_Rhodopsin_II | W8: O91af35bb0 | X8: FALSE | Y8: HmSRII | Z8: HmSRII | AA8: Phototaxis | AB8: Haloarcula_marismortui_Sensory_Rhodopsin_II_Haloarcula marismortui
A9: 12 | B9: include | C9: HmSRIII | E9: Haloarcula marismortui | F9: Archaea | G9: regulation of transducer | H9: regulation of transducer | M9: MAQEIVWYGAGAGAFFVSAVVFVWFAATRGNIRSSFYYLPPIHTSVAGAAYVAMALIAGGQLGDTVSITTLRFADWIVSTPIITYYLARLAGVDTQTRRLAVAANVVMIGVGYGFVSMSGSLRWIAFAVSTVAFIGLLYLYIKTFARKINAATASVRSLFQSLRDLTVVTWSLYPVVYFLGPLGTGIIQAPDLNFLVAVLDTIAKVGFMSILLVRYNSVETFVDSWSVAPAK | Q9: 232.0 | R9: MAQEIVWYGAGAGAFFVSAVVFVWFAATRGNIRSSFYYLPPIHTSVAGAAYVAMALIAGGQLGDTVSITTLRFADWIVSTPIITYYLARLAGVDTQTRRLAVAANVVMIGVGYGFVSMSGSLRWIAFAVSTVAFIGLLYLYIKTFARKINAATASVRSLFQSLRDLTVVTWSLYPVVYFLGPLGTGIIQAPDLNFLVAVLDTIAKVGFMSILLVRYNSVETFVDSWSVAPAK | U9: Haloarcula marismortui Sensory Rhodopsin III | V9: Haloarcula_marismortui_Sensory_Rhodopsin_III | W9: O9aaaef0fd | X9: FALSE | Y9: HmSRIII | Z9: HmSRIII | AA9: Phototaxis | AB9: Haloarcula_marismortui_Sensory_Rhodopsin_III_Haloarcula marismortui
A10: 13 | B10: include | C10: HsSRI | E10: Halobacterium salinarum | F10: Archaea | G10: regulation of transducer | H10: regulation of transducer | M10: MDAVATAYLGGAVALIVGVAFVWLLYRSLDGSPHQSALAPLAIIPVFAGLSYVGMAYDIGTVIVNGNQIVGLRYIDWLVTTPILVGYVGYAAGASRRSIIGVMVADALMIAVGAGAVVTDGTLKWALFGVSSIFHLSLFAYLYVIFPRVVPDVPEQIGLFNLLKNHIGLLWLAYPLVWLFGPAGIGEATAAGVALTYVFLDVLAKVPYVYFFYARRRVFMHSESPPAPEQATVEATAAD | Q10: 239.0 | R10: MDAVATAYLGGAVALIVGVAFVWLLYRSLDGSPHQSALAPLAIIPVFAGLSYVGMAYDIGTVIVNGNQIVGLRYIDWLVTTPILVGYVGYAAGASRRSIIGVMVADALMIAVGAGAVVTDGTLKWALFGVSSIFHLSLFAYLYVIFPRVVPDVPEQIGLFNLLKNHIGLLWLAYPLVWLFGPAGIGEATAAGVALTYVFLDVLAKVPYVYFFYARRRVFMHSESPPAPEQATVEATAAD | U10: Halobacterium salinarum Sensory Rhodopsin I | V10: Halobacterium_salinarum_Sensory_Rhodopsin_I | W10: O67713bee1 | X10: FALSE | Y10: HsSRI | Z10: HsSRI | AA10: Phototaxis | AB10: Halobacterium_salinarum_Sensory_Rhodopsin_I_Halobacterium salinarum
A11: 15 | B11: include | C11: KR1 | E11: Krokinobacter eikastus | F11: Bacteria | G11: outward proton pump | H11: outward proton pump | M11: MKFLLLLLADPTKLDPSDYVGFTFFVGAMAMMAASAFFFLSLNQFNKKWRTSVLVSGLITFIAAVHYWYMRDYWFAIQESPTFFRYVDWVLTVPLMCVEFYLILKVAGAKPALMWKLILFSVIMLVTGYFGEAVFQDQAALWGAISGAAYFYIVYEIWLGSAKKLAVAAGGDILKAHKILCWFVLVGWAIYPLGYMLGTDGWYTSILGKGSVDVAYNIADAINKIGFGLVIYALAVKKNEVDVV | Q11: 244.0 | R11: MKFLLLLLADPTKLDPSDYVGFTFFVGAMAMMAASAFFFLSLNQFNKKWRTSVLVSGLITFIAAVHYWYMRDYWFAIQESPTFFRYVDWVLTVPLMCVEFYLILKVAGAKPALMWKLILFSVIMLVTGYFGEAVFQDQAALWGAISGAAYFYIVYEIWLGSAKKLAVAAGGDILKAHKILCWFVLVGWAIYPLGYMLGTDGWYTSILGKGSVDVAYNIADAINKIGFGLVIYALAVKKNEVDVV | U11: Krokinobacter Rhodopsin-1 | V11: Krokinobacter_Rhodopsin_1 | W11: O24730b7f1 | X11: FALSE | Y11: KR1 | Z11: KR1 | AA11: Proton pump | AB11: Krokinobacter_Rhodopsin_1_Krokinobacter
A12: 17 | B12: include | C12: NR | E12: Neurospora crassa | F12: Eukaryota | G12: outward proton pump | H12: outward proton pump | M12: MIHPEQVADMLRPTTSTTSSHVPGPVPTVVPTPTEYQTLGETGHRTLWVTFALMVLSSGIFALLSWNVPTSKRLFHVITTLITVVASLSYFAMATGHATTFNCDTAWDHHKHVPDTSHQVCRQVFWGRYVDWALTTPLLLLELCLLAGVDGAHTLMAIVADVIMVLCGLFAALGEGGNTAQKWGWYTIGCFSYLFVIWHVALHGSRTVTAKGRGVSRLFTGLAVFALLLWTAYPIIWGIAGGARRTNVDTEILIYTVLDLLAKPVFGFWLLLSHRAMPETNIDLPGYWSHGLATEGRIRIGEED | Q12: 304.0 | R12: MIHPEQVADMLRPTTSTTSSHVPGPVPTVVPTPTEYQTLGETGHRTLWVTFALMVLSSGIFALLSWNVPTSKRLFHVITTLITVVASLSYFAMATGHATTFNCDTAWDHHKHVPDTSHQVCRQVFWGRYVDWALTTPLLLLELCLLAGVDGAHTLMAIVADVIMVLCGLFAALGEGGNTAQKWGWYTIGCFSYLFVIWHVALHGSRTVTAKGRGVSRLFTGLAVFALLLWTAYPIIWGIAGGARRTNVDTEILIYTVLDLLAKPVFGFWLLLSHRAMPETNIDLPGYWSHGLATEGRIRIGEED | U12: Neurospora Rhodopsin | V12: Neurospora_Rhodopsin | W12: Oa33e502bd | X12: FALSE | Y12: NR | Z12: NR | AA12: Proton pump | AB12: Neurospora_Rhodopsin_Neurospora
A13: 18 | B13: include | C13: NdR1 | E13: Nonlabens dokdonensis | F13: Bacteria | G13: outward proton pump | H13: outward proton pump | M13: MNFLLSTLEVAKMATDDYVGFTFFIGSMAMMAASAFFFLSLSQFDNKWRTSVLVSGLITFIAAVHYFYMRDYYAATDSSPTFFRYVDWTLTVPLMCVEFYLILKVAGAKLGLMWKLIFWSVVMLVTGYFGEVIALGNPTMQWVWGLVSGIAYFIIVYMIWFGEAKKLATSAGGAVLKAHNILCWFVLVGWAIYPLGYILGTEGGLFGLQLVEDPKAAQEAMDVVYNIGDAINKIGFGLVIYSLAVTSSKKVEA | Q13: 253.0 | R13: MNFLLSTLEVAKMATDDYVGFTFFIGSMAMMAASAFFFLSLSQFDNKWRTSVLVSGLITFIAAVHYFYMRDYYAATDSSPTFFRYVDWTLTVPLMCVEFYLILKVAGAKLGLMWKLIFWSVVMLVTGYFGEVIALGNPTMQWVWGLVSGIAYFIIVYMIWFGEAKKLATSAGGAVLKAHNILCWFVLVGWAIYPLGYILGTEGGLFGLQLVEDPKAAQEAMDVVYNIGDAINKIGFGLVIYSLAVTSSKKVEA | U13: Nonlabens dokdonensis Rhodopsin-1 | V13: Nonlabens_dokdonensis_Rhodopsin_1 | W13: O0c174de93 | X13: FALSE | Y13: NdR1 | Z13: NdR1 | AA13: Proton pump | AB13: Nonlabens_dokdonensis_Rhodopsin_1_Nonlabens dokdonensis
A14: 19 | B14: include | C14: NdR2 | E14: Nonlabens dokdonensis | F14: Bacteria | G14: outward sodium pump | H14: outward sodium pump | L14: 10.1016/j.jphotobiol.2017.05.004 | M14: MIQDLGNSNFENYVGATDGFSEMAYQMTSHVLTLGYAVMFAGLLYFILTIKNVDKKYRMSNILSAVVMVSAALLLYAQAGNWTESFAFDAERGKYFLVEGGDLFNNGYRYLNWLIDVPMLLFQILFVVQLTKSKLSSVRNQFWFSGAMMIITGYIGQYYEVTDLSAFFIWGAISTVFFFHILWLMNKVIKEGKVGIPKKGQKILSNIWILFLVSWFLYPGAYLMPHLGGIEGFLFNESGVVGRQITYTIADVCSKVIYGVLLGNLALVLSKNKEMIETA | Q14: 279.0 | R14: MIQDLGNSNFENYVGATDGFSEMAYQMTSHVLTLGYAVMFAGLLYFILTIKNVDKKYRMSNILSAVVMVSAALLLYAQAGNWTESFAFDAERGKYFLVEGGDLFNNGYRYLNWLIDVPMLLFQILFVVQLTKSKLSSVRNQFWFSGAMMIITGYIGQYYEVTDLSAFFIWGAISTVFFFHILWLMNKVIKEGKVGIPKKGQKILSNIWILFLVSWFLYPGAYLMPHLGGIEGFLFNESGVVGRQITYTIADVCSKVIYGVLLGNLALVLSKNKEMIETA | U14: Nonlabens dokdonensis Rhodopsin-2 | V14: Nonlabens_dokdonensis_Rhodopsin_2 | W14: O82bd83f12 | X14: FALSE | Y14: NdR2 | Z14: NdR2 | AA14: Proton pump | AB14: Nonlabens_dokdonensis_Rhodopsin_2_Nonlabens dokdonensis
A15: 20 | B15: include | C15: NmNaR | D15: NmR2 | E15: Nonlabens marinus | F15: Bacteria | G15: outward sodium pump | H15: outward sodium pump | L15: 10.1073/pnas.1403051111 | M15: MQQLGNSNFENYIGASEGFSEMAYQMTSHVLTLGYAVMLAGLLYFILTIKKVDKRFQMSNILSAVVMVSAFLLLYAQAGNWTSSFTFDIELGRYFLDPDGDLFNNGYRYLNWLIDVPMLLFQILFVVTLTKSKLSSIRNQFWFSGTMMIITGYIGQFYEVSDITWFLIWGAISTVFFFHILYLMKKVINEGKEGISTKGQKILSNIWILFLISWFLYPGAYLMPYLGGIDGFLYNESGVVGRQITYTIADVCSKVIYGVLLGNLAMTLSTKNKNEHKPA | Q15: 279.0 | R15: MQQLGNSNFENYIGASEGFSEMAYQMTSHVLTLGYAVMLAGLLYFILTIKKVDKRFQMSNILSAVVMVSAFLLLYAQAGNWTSSFTFDIELGRYFLDPDGDLFNNGYRYLNWLIDVPMLLFQILFVVTLTKSKLSSIRNQFWFSGTMMIITGYIGQFYEVSDITWFLIWGAISTVFFFHILYLMKKVINEGKEGISTKGQKILSNIWILFLISWFLYPGAYLMPYLGGIDGFLYNESGVVGRQITYTIADVCSKVIYGVLLGNLAMTLSTKNKNEHKPA | U15: Nonlabens marinus Sodium Rhodopsin | V15: Nonlabens_marinus_Sodium_Rhodopsin | W15: Oee869d2c8 | X15: FALSE | Y15: NmNaR | Z15: NmNaR | AA15: Sodium pump | AB15: Nonlabens_marinus_Sodium_Rhodopsin_Nonlabens marinus
A16: 21 | B16: include | C16: NmPR | D16: NmR1 | E16: Nonlabens marinus | F16: Bacteria | G16: outward proton pump | H16: outward proton pump | L16: 10.1073/pnas.1403051111 | M16: MKFLLLLLADPTKLDPSDYVGFTFFVGAMAMMAASAFFFLSLNQFNKKWRTSVLVSGLITFIAAVHYWYMRDYWFAIQESPTFFRYVDWVLTVPLMCVEFYLILKVAGAKPALMWKLILFSVIMLVTGYFGEAVFQDQAALWGAISGAAYFYIVYEIWLGSAKKLAVAAGGDILKAHKILCWFVLVGWAIYPLGYMLGTDGWYTSILGKGSVDVAYNIADAINKIGFGLVIYALAVKKNEVDVV | Q16: 244.0 | R16: MKFLLLLLADPTKLDPSDYVGFTFFVGAMAMMAASAFFFLSLNQFNKKWRTSVLVSGLITFIAAVHYWYMRDYWFAIQESPTFFRYVDWVLTVPLMCVEFYLILKVAGAKPALMWKLILFSVIMLVTGYFGEAVFQDQAALWGAISGAAYFYIVYEIWLGSAKKLAVAAGGDILKAHKILCWFVLVGWAIYPLGYMLGTDGWYTSILGKGSVDVAYNIADAINKIGFGLVIYALAVKKNEVDVV | U16: Nonlabens marinus Proteorhodopsin | V16: Nonlabens_marinus_Proteorhodopsin | W16: O9f21d8ceb | X16: FALSE | Y16: NmPR | Z16: NmPR | AA16: Proton pump | AB16: Nonlabens_marinus_Proteorhodopsin_Nonlabens marinus
A17: 25 | B17: include | C17: SrSRI | E17: Salinibacter ruber | F17: Bacteria | G17: regulation of transducer | H17: regulation of transducer | M17: MDPITIVYIIGTLGMLVGIPPALSLVGDEVGLDFDYLWAIPGIAALMYLLMTFDVGSVQFQGYHVPIPRYIDWALTTPLLVGYTAYIAGASRGMIAGTALADFMMIVFGLGAVVFSSTAQWVFFGLSSACHLTLLAFLYGPVRNSAFGEPPSHRRLARLLLNYVGLLWLAYPMVWLFGPGLQWVDAAGIAVIISYLDVTAKVPFIYFIYRARKNFVKVTGGEPETASGQGGAATVTSAA | Q17: 239.0 | R17: MDPITIVYIIGTLGMLVGIPPALSLVGDEVGLDFDYLWAIPGIAALMYLLMTFDVGSVQFQGYHVPIPRYIDWALTTPLLVGYTAYIAGASRGMIAGTALADFMMIVFGLGAVVFSSTAQWVFFGLSSACHLTLLAFLYGPVRNSAFGEPPSHRRLARLLLNYVGLLWLAYPMVWLFGPGLQWVDAAGIAVIISYLDVTAKVPFIYFIYRARKNFVKVTGGEPETASGQGGAATVTSAA | U17: Salinibacter ruber Sensory Rhodopsin I | V17: Salinibacter_ruber_Sensory_Rhodopsin_I | W17: O6bfd815f6 | X17: FALSE | Y17: SrSRI | Z17: SrSRI | AA17: Phototaxis | AB17: Salinibacter_ruber_Sensory_Rhodopsin_I_Salinibacter ruber
A18: 26 | B18: include | C18: VcChR1 | D18: VChR2 | E18: Volvox carteri | F18: Eukaryota | G18: cation channel | H18: non-selective cation channel | M18: MDYPVARSLIVRYPTDLGNGTVCMPRGQCYCEGWLRSRGTSIEKTIAITLQWVVFALSVACLGWYAYQAWRATCGWEEVYVALIEMMKSIIEAFHEFDSPATLWLSSGNGVVWMRYGEWLLTCPVLLIHLSNLTGLKDDYSKRTMGLLVSDVGCIVWGATSAMCTGWTKILFFLISLSYGMYTYFHAAKVYIEAFHTVPKGICRELVRVMAWTFFVAWGMFPVLFLLGTEGFGHISPYGSAIGHSILDLIAKNMWGVLGNYLRVKIHEHILLYGDIRKKQKITIAGQEMEVETLVAEEEDDTVKQSTAKYASRDSFITMRNRMREKGLEVRASLDAGGGDSGMEAGGGGAAHAQPHMAKPGTELGKTMSASFTNGAATSLEPGRVILAVPDISMVDFFREQFAQLPVPYEVVPALGAENTVQLVQQAAMLGGCDFVLMHPEFLRDRGPTGLLPQVKMMGQRTAAFGWSQMGPMRDLIESSGVGAWLEGPSFGSGISQAALQQLVVKMQQAKRMAAMGSMMGGGMGNGMGMGMGMGMGMGMGNGMGNGMGMGNGMGNGMGMGNGMGNGMGMGNGMGMGNGMGMGNGMGMGNGMGNGMGNGMGMGNGMGNGMGNGMGNGMGNGMGNGMGMGNGMGMGNGMGNGMGNGMGNGMGNGMGMMTPGAMGMGMGGMGNLAAAAGNAMYGGGGGGGGSTMGSGNAAMMTGLVMGGGNGVGAGPGGVVANLGSSALQPQSQMMGGGNVVGMSSPQLQLQQSSSMPLGGLAPNRIGNNPLFGAAPSPLHSQPGASPTGLSSPQLGMGAMLPAGTSVGAGGGSVGPTETDMLQQLMTEINRLKDELGE | Q18: 837.0 | R18: MDYPVARSLIVRYPTDLGNGTVCMPRGQCYCEGWLRSRGTSIEKTIAITLQWVVFALSVACLGWYAYQAWRATCGWEEVYVALIEMMKSIIEAFHEFDSPATLWLSSGNGVVWMRYGEWLLTCPVLLIHLSNLTGLKDDYSKRTMGLLVSDVGCIVWGATSAMCTGWTKILFFLISLSYGMYTYFHAAKVYIEAFHTVPKGICRELVRVMAWTFFVAWGMFPVLFLLGTEGFGHISPYGSAIGHSILDLIAKNMWGVLGNYLRVKIHEHILLYGDIRKKQKITIAGQEMEVETLVAEEEDDTVKQSTAKYASRDSFITMRNRMREKGLEVRASLDAGGGDSGMEAGGGGAAHAQPHMAKPGTELGKTMSASFTNGAATSLEPGRVILAVPDISMVDFFREQFAQLPVPYEVVPALGAENTVQLVQQAAMLGGCDFVLMHPEFLRDRGPTGLLPQVKMMGQRTAAFGWSQMGPMRDLIESSGVGAWLEGPSFGSGISQAALQQLVVKMQQAKRMAAMGSMMGGGMGNGMGMGMGMGMGMGMGNGMGNGMGMGNGMGNGMGMGNGMGNGMGMGNGMGMGNGMGMGNGMGMGNGMGNGMGNGMGMGNGMGNGMGNGMGNGMGNGMGNGMGMGNGMGMGNGMGNGMGNGMGNGMGNGMGMMTPGAMGMGMGGMGNLAAAAGNAMYGGGGGGGGSTMGSGNAAMMTGLVMGGGNGVGAGPGGVVANLGSSALQPQSQMMGGGNVVGMSSPQLQLQQSSSMPLGGLAPNRIGNNPLFGAAPSPLHSQPGASPTGLSSPQLGMGAMLPAGTSVGAGGGSVGPTETDMLQQLMTEINRLKDELGE | S18: 330.0 | T18: 30.0 | U18: Volvox carteri Channelrhodopsin-1 | V18: Volvox_carteri_Channelrhodopsin_1 | W18: Od1cf04ce5 | X18: FALSE | Y18: VcChR1 | Z18: VcChR1 | AA18: Cation channel | AB18: Volvox_carteri_Channelrhodopsin_1_Volvox carteri
A19: 27 | B19: include | C19: VcChR2 | D19: VChR1 | E19: Volvox carteri | F19: Eukaryota | G19: cation channel | H19: non-selective cation channel | M19: MDHPVARSLIGSSYTNLNNGSIVIPSDACFCMKWLKSKGSPVALKMANALQWAAFALSVIILIYYAYATWRTTCGWEEVYVCCVELTKVVIEFFHEFDEPGMLYLANGNRVLWLRYGEWLLTCPVILIHLSNLTGLKDDYNKRTMRLLVSDVGTIVWGATAAMSTGYIKVIFFLLGCMYGANTFFHAAKVYIESYHTVPKGLCRQLVRAMAWLFFVSWGMFPVLFLLGPEGFGHLSVYGSTIGHTIIDLLSKNCWGLLGHFLRLKIHEHILLYGDIRKVQKIRVAGEELEVETLMTEEAPDTVKKSTAQYANRESFLTMRDKLKEKGFEVRASLDNSGIDAVINHNNNYNNALANAAAAVGKPGMELSKLDHVAANAAGMGGIADHVATTSGAISPGRVILAVPDISMVDYFREQFAQLPVQYEVVPALGADNAVQLVVQAAGLGGCDFVLLHPEFLRDKSSTSLPARLRSIGQRVAAFGWSPVGPVRDLIESAGLDGWLEGPSFGLGISLPNLASLVLRMQHARKMAAMLGGMGGMLGSNLMSGSGGVGLMGAGSPGGGGGAMGVGMTGMGMVGTNAMGRGAVGNSVANASMGGGSAGMGMGMMGMVGAGVGGQQQMGANGMGPTSFQLGSNPLYNTAPSPLSSQPGGDASAAAAAAAAAAATGAASNSMNAMQAGGSVRNSGILAGGLGSMMGPPGAPAAPTAAATAAPAVTMGAPGGGGAAASEAEMLQQLMAEINRLKSELGE | Q19: 747.0 | R19: MDHPVARSLIGSSYTNLNNGSIVIPSDACFCMKWLKSKGSPVALKMANALQWAAFALSVIILIYYAYATWRTTCGWEEVYVCCVELTKVVIEFFHEFDEPGMLYLANGNRVLWLRYGEWLLTCPVILIHLSNLTGLKDDYNKRTMRLLVSDVGTIVWGATAAMSTGYIKVIFFLLGCMYGANTFFHAAKVYIESYHTVPKGLCRQLVRAMAWLFFVSWGMFPVLFLLGPEGFGHLSVYGSTIGHTIIDLLSKNCWGLLGHFLRLKIHEHILLYGDIRKVQKIRVAGEELEVETLMTEEAPDTVKKSTAQYANRESFLTMRDKLKEKGFEVRASLDNSGIDAVINHNNNYNNALANAAAAVGKPGMELSKLDHVAANAAGMGGIADHVATTSGAISPGRVILAVPDISMVDYFREQFAQLPVQYEVVPALGADNAVQLVVQAAGLGGCDFVLLHPEFLRDKSSTSLPARLRSIGQRVAAFGWSPVGPVRDLIESAGLDGWLEGPSFGLGISLPNLASLVLRMQHARKMAAMLGGMGGMLGSNLMSGSGGVGLMGAGSPGGGGGAMGVGMTGMGMVGTNAMGRGAVGNSVANASMGGGSAGMGMGMMGMVGAGVGGQQQMGANGMGPTSFQLGSNPLYNTAPSPLSSQPGGDASAAAAAAAAAAATGAASNSMNAMQAGGSVRNSGILAGGLGSMMGPPGAPAAPTAAATAAPAVTMGAPGGGGAAASEAEMLQQLMAEINRLKSELGE | S19: 330.0 | T19: 30.0 | U19: Volvox carteri Channelrhodopsin-2 | V19: Volvox_carteri_Channelrhodopsin_2 | W19: O2a0ab9171 | X19: FALSE | Y19: VcChR2 | Z19: VcChR2 | AA19: Cation channel | AB19: Volvox_carteri_Channelrhodopsin_2_Volvox carteri
A20: 28 | B20: include | C20: ZipACR | E20: Zachrysium infestans | F20: Eukaryota | G20: anion channel | H20: non-selective anion channel | M20: MAALHQALEELGQGASRHLLYRAPEEMVYGKWVEANPRCIELHDHSDYVYVFQLCFAVVCACQVIFMFTRAPNVGWEAIYLPLAEVVTYSIAANGEGVLRMADGRYFNFAKLAGWAVCCPIMLIQIGGMAQIKYRTIPLNNVVLAASLNRIIFGMASAITASDPARWGFYFCAWICYLTEVGITLTIMAVAISDFSKIKTELGQWVVGRIQTMRIIFLVAWTSFPVVWVLGYTGFCVIHEDYIALLYLFADLLSKNTWGVMMWHTTWVKLNGKWDREFAAAGGHEALKKALEQDVEIGAGEKNQNQLTARQ | Q20: 311.0 | R20: MAALHQALEELGQGASRHLLYRAPEEMVYGKWVEANPRCIELHDHSDYVYVFQLCFAVVCACQVIFMFTRAPNVGWEAIYLPLAEVVTYSIAANGEGVLRMADGRYFNFAKLAGWAVCCPIMLIQIGGMAQIKYRTIPLNNVVLAASLNRIIFGMASAITASDPARWGFYFCAWICYLTEVGITLTIMAVAISDFSKIKTELGQWVVGRIQTMRIIFLVAWTSFPVVWVLGYTGFCVIHEDYIALLYLFADLLSKNTWGVMMWHTTWVKLNGKWDREFAAAGGHEALKKALEQDVEIGAGEKNQNQLTARQ | U20: Zachrysium infestans Anion Channelrhodopsin | V20: Zachrysium_infestans_Anion_Channelrhodopsin | W20: O6e2b9cfeb | X20: FALSE | Y20: ZipACR | Z20: ZipACR | AA20: Anion channel | AB20: Zachrysium_infestans_Anion_Channelrhodopsin_Zachrysium infestans
A21: 29 | B21: include | C21: NeoR | E21: Rhizoclosmatium globosum | F21: Eukaryota | G21: regulation of guanylyl cyclase | H21: regulation of guanylyl cyclase | M21: MSALTKARDALANTSAKDPYHEAKPMGFVWLNFGMWLAAVGYTIHQRLFGGYHTKAVDRGNSDFIYKGTTFVFIVAVCFTYLGYIGTKSAAKKSMTFVLMMTCGVVATSWFLLYLRAGITLLDGAGHPVDIIRHLEWAHDEANLAYFLGLLTSADQWTIGRTILESHGLLLFGFLASIARHPYDELFATISMCIYLACLQDIISMFQKAIDGEVDNKVDTWTLRRCRDITIFAWSYITLAWYLVRHGFWSFETGELHIALGEFCAKVVLMLIFVNNSVEEAQINTVSQMETLTSSLDEQMAASDKLLEKLIPAGVLDQLKSGKATGAEEYSCVTVFFSDIANFTPLSQRTSTKDMLASLNNMWIEYDKISKKWGMYKVETIGDAFLGVVGAPDRVPDHAERAAEFSIDIIDMIKDFRLVTGEPIQIRAGLNSGPVTAGILGESNPHWCIVGDTVTIASKMEATSKHMKIHIAESTFNLIKSSGKFRTSDSEPVTIKGNVINTFFIEGRA | Q21: 509.0 | R21: MSALTKARDALANTSAKDPYHEAKPMGFVWLNFGMWLAAVGYTIHQRLFGGYHTKAVDRGNSDFIYKGTTFVFIVAVCFTYLGYIGTKSAAKKSMTFVLMMTCGVVATSWFLLYLRAGITLLDGAGHPVDIIRHLEWAHDEANLAYFLGLLTSADQWTIGRTILESHGLLLFGFLASIARHPYDELFATISMCIYLACLQDIISMFQKAIDGEVDNKVDTWTLRRCRDITIFAWSYITLAWYLVRHGFWSFETGELHIALGEFCAKVVLMLIFVNNSVEEAQINTVSQMETLTSSLDEQMAASDKLLEKLIPAGVLDQLKSGKATGAEEYSCVTVFFSDIANFTPLSQRTSTKDMLASLNNMWIEYDKISKKWGMYKVETIGDAFLGVVGAPDRVPDHAERAAEFSIDIIDMIKDFRLVTGEPIQIRAGLNSGPVTAGILGESNPHWCIVGDTVTIASKMEATSKHMKIHIAESTFNLIKSSGKFRTSDSEPVTIKGNVINTFFIEGRA | S21: 287.0 | T21: 12.0 | U21: Neorhodopsin | V21: Neorhodopsin | W21: O46c416e81 | X21: FALSE | Y21: NeoR | Z21: NeoR | AA21: Cyclase | AB21: Neorhodopsin_Rhizoclosmatium globosum
A22: 30 | B22: include | C22: HsBR | D22: bacteriorhodopsin | E22: Halobacterium salinarum | F22: Archaea | G22: outward proton pump | H22: outward proton pump | I22: 1C3W | J22: X-ray | K22: 45809 | L22: Luecke et al., JMB, 1999 | N22: 1C3W | O22: TGRPEWIWLALGTALMGLGTLYFLVKGMGVSDPDAKKFYAITTLVPAIAFTMYLSMLLGYGLTMVPFGGEQNPIYWARYADWLFTTPLLLLDLALLVDADQGTILALVGADGIMIGTGLVGALTKVYSYRFVWWAISTAAMLYILYVLFFGFSMRPEVASTFKVLRNVTVVLWSAYPVVWLIGSEGAGIVPLNIETLLFMVLDVSAKVGFGLILLRSRAIFG | P22: P02945 | Q22: 222.0 | R22: TGRPEWIWLALGTALMGLGTLYFLVKGMGVSDPDAKKFYAITTLVPAIAFTMYLSMLLGYGLTMVPFGGEQNPIYWARYADWLFTTPLLLLDLALLVDADQGTILALVGADGIMIGTGLVGALTKVYSYRFVWWAISTAAMLYILYVLFFGFSMRPEVASTFKVLRNVTVVLWSAYPVVWLIGSEGAGIVPLNIETLLFMVLDVSAKVGFGLILLRSRAIFG | U22: HsBR | V22: HsBR | W22: O21386786a | X22: TRUE | Y22: HsBR | Z22: HsBR | AA22: Proton pump | AB22: HsBR_Halobacterium salinarum
A23: 31 | B23: include | C23: archaerhodopsin-1 | D23: AR1 | E23: Halorubrum ezzemoulense | F23: Archaea | G23: outward proton pump | H23: outward proton pump | I23: 1UAZ | J23: X-ray | K23: 45750 | L23: Enami et al., J Photosci., 2003 | N23: 1UAZ | O23: TAAVGADLLGDGRPETLWLGIGTLLMLIGTFYFIVKGWGVTDKEAREYYSITILVPGIASAAYLSMFFGIGLTEVQVGSEMLDIYYARYADWLFTTPLLLLDLALLAKVDRVSIGTLVGVDALMIVTGLVGALSHTPLARYTWWLFSTICMIVVLYFLATSLRAAAKERGPEVASTFNTLTALVLVLWTAYPILWIIGTEGAGVVGLGIETLLFMVLDVTAKVGFGFILLRSRAIL | P23: P69051 | Q23: 236.0 | R23: TAAVGADLLGDGRPETLWLGIGTLLMLIGTFYFIVKGWGVTDKEAREYYSITILVPGIASAAYLSMFFGIGLTEVQVGSEMLDIYYARYADWLFTTPLLLLDLALLAKVDRVSIGTLVGVDALMIVTGLVGALSHTPLARYTWWLFSTICMIVVLYFLATSLRAAAKERGPEVASTFNTLTALVLVLWTAYPILWIIGTEGAGVVGLGIETLLFMVLDVTAKVGFGFILLRSRAIL | U23: archaerhodopsin-1 | V23: archaerhodopsin_1 | W23: Oba4f6277e | X23: TRUE | Y23: AR1 | Z23: AR1 | AA23: Proton pump | AB23: archaerhodopsin_1_Halorubrum ezzemoulense
A24: 32 | B24: include | C24: archaerhodopsin-2 | D24: AR2 | E24: Halobacterium sp. AUS-2 | F24: Archaea | G24: outward proton pump | H24: outward proton pump | I24: 1VGO | J24: X-ray | K24: 45779 | L24: Enami et al., JMB., 2006 | N24: 1VGO | O24: DLLNDGRPETLWLGIGTLLMLIGTFYFIARGWGVTDKEAREYYAITILVPGIASAAYLAMFFGIGVTEVELASGTVLDIYYARYADWLFTTPLLLLDLALLAKVDRVTIGTLIGVDALMIVTGLIGALSKTPLARYTWWLFSTIAFLFVLYYLLTSLRSAAAKRSEEVRSTFNTLTALVAVLWTAYPILWIVGTEGAGVVGLGIETLAFMVLDVTAKVGFGFVLLRSRAILGETE | P24: P29563 | Q24: 235.0 | R24: DLLNDGRPETLWLGIGTLLMLIGTFYFIARGWGVTDKEAREYYAITILVPGIASAAYLAMFFGIGVTEVELASGTVLDIYYARYADWLFTTPLLLLDLALLAKVDRVTIGTLIGVDALMIVTGLIGALSKTPLARYTWWLFSTIAFLFVLYYLLTSLRSAAAKRSEEVRSTFNTLTALVAVLWTAYPILWIVGTEGAGVVGLGIETLAFMVLDVTAKVGFGFVLLRSRAILGETE | U24: archaerhodopsin-2 | V24: archaerhodopsin_2 | W24: O19e22f4f9 | X24: TRUE | Y24: AR2 | Z24: AR2 | AA24: Proton pump | AB24: archaerhodopsin_2_Halobacterium sp. AUS-2
A25: 33 | B25: include | C25: archaerhodopsin-3 | D25: Arch, AR3 | E25: Halorubrum sodomense | F25: Archaea | G25: outward proton pump | H25: outward proton pump | I25: 6GUX | J25: X-ray | K25: 45717 | L25: Bada Juarez et al., Nat Commun., 2021 | N25: 6GUX | O25: AGYDLLGDGRPETLWLGIGTLLMLIGTFYFLVRGWGVTDKDAREYYAVTILVPGIASAAYLSMFFGIGLTEVTVGGEMLDIYYARYADWLFTTPLLLLDLALLAKVDRVTIGTLVGVDALMIVTGLIGALSHTAIARYSWWLFSTICMIVVLYFLATSLRSAAKERGPEVASTFNTLTALVLVLWTAYPILWIIGTEGAGVVGLGIETLLFMVLDVTAKVGFGFILLRSRAILGDTEAPE | P25: P96787 | Q25: 240.0 | R25: AGYDLLGDGRPETLWLGIGTLLMLIGTFYFLVRGWGVTDKDAREYYAVTILVPGIASAAYLSMFFGIGLTEVTVGGEMLDIYYARYADWLFTTPLLLLDLALLAKVDRVTIGTLVGVDALMIVTGLIGALSHTAIARYSWWLFSTICMIVVLYFLATSLRSAAKERGPEVASTFNTLTALVLVLWTAYPILWIIGTEGAGVVGLGIETLLFMVLDVTAKVGFGFILLRSRAILGDTEAPE | U25: archaerhodopsin-3 | V25: archaerhodopsin_3 | W25: Of0c145803 | X25: TRUE | Y25: Arch, AR3 | Z25: AR3 | AA25: Proton pump | AB25: archaerhodopsin_3_Halorubrum sodomense
A26: 34 | B26: include | C26: deltarhodopsin-3 | D26: dR3 | E26: Natrinema thermotolerans | F26: Archaea | G26: outward proton pump | H26: outward proton pump | I26: 4FBZ | J26: X-ray | K26: 45840 | L26: Zhang et al., Proteins, 2013 | N26: 4FBZ | O26: MAATVGPESIWLWIGTIGMTLGTLYFVGRGRGVRDRKMQEFYIITTFITTIAAAMYFAMATGFGVTEVVVGDEALTIYWARYADWLFTTPLLLLDLGLLAGANRNTIATLIGLDVFMIGTGMIAAFAATPGTRIAWWGISTGALLALLYVLVGTLSKDARGQSPEVASLFGRLRNLVIVLWLLYPVVWILGTEGTFGILPLYWETAAFMVLDLSAKVGFGVVLLRSRSVLRRVVTPTA | P26: I4DST7 | Q26: 238.0 | R26: MAATVGPESIWLWIGTIGMTLGTLYFVGRGRGVRDRKMQEFYIITTFITTIAAAMYFAMATGFGVTEVVVGDEALTIYWARYADWLFTTPLLLLDLGLLAGANRNTIATLIGLDVFMIGTGMIAAFAATPGTRIAWWGISTGALLALLYVLVGTLSKDARGQSPEVASLFGRLRNLVIVLWLLYPVVWILGTEGTFGILPLYWETAAFMVLDLSAKVGFGVVLLRSRSVLRRVVTPTA | U26: deltarhodopsin-3 | V26: deltarhodopsin_3 | W26: Oa63776b5e | X26: TRUE | Y26: dR3 | Z26: dR3 | AA26: Proton pump | AB26: deltarhodopsin_3_Natrinema thermotolerans
A27: 35 | B27: include | C27: cruxrhodopsin-3 | D27: cR3, Cop3 | E27: Haloarcula vallismortis | F27: Archaea | G27: outward proton pump | H27: outward proton pump | I27: 4JR8 | J27: X-ray | K27: 45718 | L27: Chan et al., PLOS ONE, 2014 | N27: 4JR8 | O27: PEGEAIWLWLGTAGMFLGMLYFIARGWGETDSRRQKFYIATILITAIAFVNYLAMALGFGLTIVEIAGEQRPIYWARYSDWLFTTPLLLYDLGLLAGADRNTISSLVSLDVLMIGTGLVATLSAGSGVLSAGAERLVWWGISTAFLLVLLYFLFSSLSGRVADLPSDTRSTFKTLRNLVTVVWLVYPVWWLVGTEGIGLVGIGIETAGFMVIDLVAKVGFGIILLRSHGVLDGA | P27: P94854 | Q27: 234.0 | R27: PEGEAIWLWLGTAGMFLGMLYFIARGWGETDSRRQKFYIATILITAIAFVNYLAMALGFGLTIVEIAGEQRPIYWARYSDWLFTTPLLLYDLGLLAGADRNTISSLVSLDVLMIGTGLVATLSAGSGVLSAGAERLVWWGISTAFLLVLLYFLFSSLSGRVADLPSDTRSTFKTLRNLVTVVWLVYPVWWLVGTEGIGLVGIGIETAGFMVIDLVAKVGFGIILLRSHGVLDGA | U27: cruxrhodopsin-3 | V27: cruxrhodopsin_3 | W27: O46bf847f3 | X27: TRUE | Y27: cR3, Cop3 | Z27: cR3 | AA27: Proton pump | AB27: cruxrhodopsin_3_Haloarcula vallismortis
A28: 36 | B28: include | C28: HmBRI-D94N | D28: Haloarcula marismortui bacteriorhodopsin I D94N | E28: Haloarcula marismortui ATCC 43049 | F28: Archaea | G28: outward proton pump | H28: outward proton pump | I28: 4PXK | J28: X-ray | K28: 45779 | L28: Shevchenko et al., PLOS ONE, 2014 | N28: 4PXK | O28: APGSEGIWLWLGTAGMFLGMLYFIARGWGETDGRRQKFYIATILITAIAFVNYLAMALGFGLTFIEFGGEQHPIYWARYTDWLFTTPLLLYNLGLLAGADRNTIYSLVSLDVLMIGTGVVATLSAGSGVLSAGAERLVWWGISTAFLLVLLYFLFSSLSGRVANLPSDTRSTFKTLRNLVTVVWLVYPVWWLVGSEGLGLVGIGIETAGFMVIDLVAKVGFGIILLRSHGVLDGAA | P28: Q5UXY6 | Q28: 236.0 | R28: APGSEGIWLWLGTAGMFLGMLYFIARGWGETDGRRQKFYIATILITAIAFVNYLAMALGFGLTFIEFGGEQHPIYWARYTDWLFTTPLLLYNLGLLAGADRNTIYSLVSLDVLMIGTGVVATLSAGSGVLSAGAERLVWWGISTAFLLVLLYFLFSSLSGRVANLPSDTRSTFKTLRNLVTVVWLVYPVWWLVGSEGLGLVGIGIETAGFMVIDLVAKVGFGIILLRSHGVLDGAA | U28: HmBRI-D94N | V28: HmBRI_D94N | W28: O71a387ec0 | X28: TRUE | Y28: HmBRI | Z28: HmBRI-D94N | AA28: Proton pump | AB28: HmBRI_D94N_Haloarcula marismortui ATCC 43049
A29: 37 | B29: include | C29: HwBR | E29: Haloquadratum walsbyi DSM 16790 | F29: Archaea | G29: outward proton pump | H29: outward proton pump | I29: 5KKH | J29: X-ray | K29: 45659 | L29: Broecker et al., Cryst Growth Des, 2016 | N29: 5KHH | O29: SSRRQYQEKYKQVEQYMSFHKLPADFRQKIHDYYEHRYQGKMFDEDSILGELNGPLREEIVNFNRKLVASMPLFANADPNFVTAMLTKLKFEVFQPGDYIIREGTIGKKMYFIQHGVVSVLTKGNKEMKLSDGSYFGEICLLTRGRRTASVRADTYCRLYSLSVDNFNEVLEEYPMMRRAFETVAIDRLDRIGK | P29: O88703 | Q29: 194.0 | R29: SSRRQYQEKYKQVEQYMSFHKLPADFRQKIHDYYEHRYQGKMFDEDSILGELNGPLREEIVNFNRKLVASMPLFANADPNFVTAMLTKLKFEVFQPGDYIIREGTIGKKMYFIQHGVVSVLTKGNKEMKLSDGSYFGEICLLTRGRRTASVRADTYCRLYSLSVDNFNEVLEEYPMMRRAFETVAIDRLDRIGK | U29: HwBR | V29: HwBR | W29: O55bb59799 | X29: TRUE | Y29: HwBR | Z29: HwBR | AA29: Proton pump | AB29: HwBR_Haloquadratum walsbyi DSM 16790
A30: 38 | B30: include | C30: GR | D30: Gloeobacter rhodopsin | E30: Gloeobacter violaceus PCC 7421 | F30: Bacteria | G30: outward proton pump | H30: outward proton pump | I30: 6NWD | J30: X-ray | K30: 2.0 | L30: Morizumi et al., Sci. Rep., 2019 | N30: 6NWD | O30: DSLTYGQFNLVYNAFSFAIAAMFASALFFFSAQALVGQRYRLALLVSAIVVSIAGYHYFRIFNSWDAAYVLENGVYSLTSEKFNDAYRYVDWLLTVPLLLVETVAVLTLPAKEARPLLIKLTVASVLMIATGYPGEISDDITTRIIWGTVSTIPFAYILYVLWVELSRSLVRQPAAVQTLVRNMRWLLLLSWGVYPIAYLLPMLGVSGTSAAVGVQVGYTIADVLAKPVFGLLVFAIALVKTKADQ | P30: Q7NP59 | Q30: 246.0 | R30: DSLTYGQFNLVYNAFSFAIAAMFASALFFFSAQALVGQRYRLALLVSAIVVSIAGYHYFRIFNSWDAAYVLENGVYSLTSEKFNDAYRYVDWLLTVPLLLVETVAVLTLPAKEARPLLIKLTVASVLMIATGYPGEISDDITTRIIWGTVSTIPFAYILYVLWVELSRSLVRQPAAVQTLVRNMRWLLLLSWGVYPIAYLLPMLGVSGTSAAVGVQVGYTIADVLAKPVFGLLVFAIALVKTKADQ | U30: GR | V30: GR | W30: Of214a7d42 | X30: TRUE | Y30: GR | Z30: GR | AA30: Proton pump | AB30: GR_Gloeobacter violaceus PCC 7421
A31: 39 | B31: include | C31: TR | D31: thermophilic rhodopsin | E31: Thermus thermophilus JL-18 | F31: Bacteria | G31: outward proton pump | H31: outward proton pump | I31: 5AZD | J31: X-ray | K31: 45810 | L31: Tsukamoto et al., JBC, 2016 | N31: 5AZD | O31: MLPELSFGEYWLVFNMLSLTIAGMLAAFVFFLLARSYVAPRYHIALYLSALIVFIAGYHYLRIFESWVGAYQLQDGVYVPTGKPFNDFYRYADWLLTVPLLLLELILVLGLTAARTWNLSIKLVVASVLMLALGYVGEVNTEPGPRTLWGALSSIPFFYILYVLWVELGQAIREAKFGPRVLELLGATRLVLLMSWGFYPIAYALGTWLPGGAAQEVAIQIGYSLADLIAPIYGLLVFAIARAKSLEEGF | P31: H9ZSC3 | Q31: 250.0 | R31: MLPELSFGEYWLVFNMLSLTIAGMLAAFVFFLLARSYVAPRYHIALYLSALIVFIAGYHYLRIFESWVGAYQLQDGVYVPTGKPFNDFYRYADWLLTVPLLLLELILVLGLTAARTWNLSIKLVVASVLMLALGYVGEVNTEPGPRTLWGALSSIPFFYILYVLWVELGQAIREAKFGPRVLELLGATRLVLLMSWGFYPIAYALGTWLPGGAAQEVAIQIGYSLADLIAPIYGLLVFAIARAKSLEEGF | U31: TR | V31: TR | W31: Oebe021079 | X31: TRUE | Y31: TR | Z31: TR | AA31: Proton pump | AB31: TR_Thermus thermophilus JL-18
A32: 40 | B32: include | C32: XR | D32: Xanthorhodopsin | E32: Salinibacter ruber | F32: Bacteria | G32: outward proton pump | H32: outward proton pump | I32: 3DDL | J32: X-ray | K32: 45901 | L32: Luecke et al., PNAS, 2008 | N32: 3DDL | O32: ELPTLTPGQYSLVFNMFSFTVATMTASFVFFVLARNNVAPKYRISMMVSALVVFIAGYHYFRITSSWEAAYALQNGMYQPTGELFNDAYRYVDWLLTVPLLTVELVLVMGLPKNERGPLAAKLGFLAALMIVLGYPGEVSENAALFGTRGLWGFLSTIPFVWILYILFTQLGDTIQRQSSRVSTLLGNARLLLLATWGFYPIAYMIPMPSNTPGTIVALQVGYTIADVLAKAGYGVLIYNIAKAKSEEEGFN | P32: Q2S2F8 | Q32: 252.0 | R32: ELPTLTPGQYSLVFNMFSFTVATMTASFVFFVLARNNVAPKYRISMMVSALVVFIAGYHYFRITSSWEAAYALQNGMYQPTGELFNDAYRYVDWLLTVPLLTVELVLVMGLPKNERGPLAAKLGFLAALMIVLGYPGEVSENAALFGTRGLWGFLSTIPFVWILYILFTQLGDTIQRQSSRVSTLLGNARLLLLATWGFYPIAYMIPMPSNTPGTIVALQVGYTIADVLAKAGYGVLIYNIAKAKSEEEGFN | U32: XR | V32: XR | W32: O6e029fb0c | X32: TRUE | Y32: XR | Z32: XR | AA32: Proton pump | AB32: XR_Salinibacter ruber
A33: 41 | B33: include | C33: RxR | E33: Rubrobacter xylanophilus DSM 9941 | F33: Bacteria | G33: outward proton pump | H33: outward proton pump | I33: 6KFQ | J33: X-ray | K33: 45870 | L33: Hayashi et al., J Phys Chem B, 2020 | N33: 6KFQ | O33: MEALWLWIGFVGMLLGTLYFAFLLTNAPEGTRYFFVITATITGIAAIAYLVMATGSGSTVLPDGREFYWARYIDWVITTPLLLLDLCLLALADPRRNVTFIASLIALDVVMILTGLWAGATVNVAGRAILFIISTAAFIGVLYLLVSRLFAEASRRTPAVAQIFRTLAVLTIVLWICYPIVWLIGTEGFGAVSLSVEVFLFMVLDLLAKVGFGLLLLSSRQALSDIGSG | P33: Q1AUE6 | Q33: 229.0 | R33: MEALWLWIGFVGMLLGTLYFAFLLTNAPEGTRYFFVITATITGIAAIAYLVMATGSGSTVLPDGREFYWARYIDWVITTPLLLLDLCLLALADPRRNVTFIASLIALDVVMILTGLWAGATVNVAGRAILFIISTAAFIGVLYLLVSRLFAEASRRTPAVAQIFRTLAVLTIVLWICYPIVWLIGTEGFGAVSLSVEVFLFMVLDLLAKVGFGLLLLSSRQALSDIGSG | U33: RxR | V33: RxR | W33: O9bf555c17 | X33: TRUE | Y33: RxR | Z33: RxR | AA33: Proton pump | AB33: RxR_Rubrobacter xylanophilus DSM 9941
A34: 42 | B34: include | C34: Med12BPR | E34: uncultured bacterium | F34: Bacteria | G34: outward proton pump | H34: outward proton pump | I34: 4JQ6 | J34: X-ray | K34: 45718 | L34: Ran et al., Acta Crystallogr D Biol Crystallogr, 2013 | N34: 4JQ6 | O34: DYVGISFWLAAAIMLASTVFFFVERSDVPVKWKTSLTVAGLVTGVAFWHYLYMRGVWIYAGETPTVFRYIDWLITVPLQIIEFYLIIAAAVFWKLLIASLVMLIGGFIGEAGLGDVVVWWIVGMIAWLYIIYEIFLGAASQQAFNTIKWIVTVGWAIYPIGYAWGYFGDGLNEDALNIVYNLADLINKAAFGLAIWAAAMKDK | P34: Q4PP54 | Q34: 203.0 | R34: DYVGISFWLAAAIMLASTVFFFVERSDVPVKWKTSLTVAGLVTGVAFWHYLYMRGVWIYAGETPTVFRYIDWLITVPLQIIEFYLIIAAAVFWKLLIASLVMLIGGFIGEAGLGDVVVWWIVGMIAWLYIIYEIFLGAASQQAFNTIKWIVTVGWAIYPIGYAWGYFGDGLNEDALNIVYNLADLINKAAFGLAIWAAAMKDK | U34: Med12BPR | V34: Med12BPR | W34: O34c1e6315 | X34: TRUE | Y34: Med12BPR | Z34: Med12BPR | AA34: Proton pump | AB34: Med12BPR_uncultured bacterium
A35: 43 | B35: include | C35: HOT75BPR-D97N | E35: gamma proteobacterium 'Hot 75m4 | F35: Bacteria | G35: outward proton pump | H35: outward proton pump | I35: 4KLY | J35: X-ray | K35: 45840 | L35: Ran et al., Acta Crystallogr D Biol Crystallogr, 2013 | N35: 4KLY | O35: GDLDISDTVGVSFWLVTAGLAATVFFFVERDQVSAKWKTSLTVSGLITGIAFWHYLYRGVWIDTGDTPTVFRYINWLLTVPLQVVEFYLILAACTSVAASLFKKLLAGSLVLGAGFAGEAGLAPVLPAFIIGAGWLYIYELYGEGKAAVSTASPAVNSAYNAIIVVGWAIYPAGYAAGYLVYASNLNLIYNLADFVNKILFGLIIWNVAVKESSNALEHHH | P35: Q9AFF7 | Q35: 221.0 | R35: GDLDISDTVGVSFWLVTAGLAATVFFFVERDQVSAKWKTSLTVSGLITGIAFWHYLYRGVWIDTGDTPTVFRYINWLLTVPLQVVEFYLILAACTSVAASLFKKLLAGSLVLGAGFAGEAGLAPVLPAFIIGAGWLYIYELYGEGKAAVSTASPAVNSAYNAIIVVGWAIYPAGYAAGYLVYASNLNLIYNLADFVNKILFGLIIWNVAVKESSNALEHHH | U35: HOT75BPR-D97N | V35: HOT75BPR_D97N | W35: O87fbcd72d | X35: TRUE | Y35: HOT75BPR-D97N | Z35: H75BPR-D97N | AA35: Proton pump | AB35: HOT75BPR_D97N_gamma proteobacterium 'Hot 75m4
A36: 44 | B36: include | C36: GPR-A18L | E36: uncultured Gammaproteobacteria bacterium | F36: Bacteria | G36: outward proton pump | H36: outward proton pump | I36: 8CQC | J36: cryo-EM | K36: 45871 | L36: Hirschi et al., Nat Commun., 2024 | N36: 8CQC | O36: DASDYTGVSFWLVTAALLASTVFFFVERDRVSAKWKTSLTVSGLVTGIAFWHYMYMRGVWIETGDSPTVFRYIDWLLTVPLLICEFYLILAAATNVAGSLFKKLLVGSLVMLVFGYMGEAGIMAAWPAFIIGCLAWVYMIYELWAGEGKSACNTASPAVQSAYNTMMYIIIFGWAIYPVGYFTGYLNLNLIYNLADFVNKILFGLIIWNVAVKESSN | P36: Q6J4G7 | Q36: 217.0 | R36: DASDYTGVSFWLVTAALLASTVFFFVERDRVSAKWKTSLTVSGLVTGIAFWHYMYMRGVWIETGDSPTVFRYIDWLLTVPLLICEFYLILAAATNVAGSLFKKLLVGSLVMLVFGYMGEAGIMAAWPAFIIGCLAWVYMIYELWAGEGKSACNTASPAVQSAYNTMMYIIIFGWAIYPVGYFTGYLNLNLIYNLADFVNKILFGLIIWNVAVKESSN | U36: GPR-A18L | V36: GPR_A18L | W36: Oc98c7da8d | X36: TRUE | Y36: GPR-A18L | Z36: GPR-A18L | AA36: Proton pump | AB36: GPR_A18L_uncultured Gammaproteobacteria bacterium
A37: 45 | B37: include | C37: ESR | E37: Exiguobacterium artemiae | F37: Bacteria | G37: outward proton pump | H37: outward proton pump | I37: 4HYJ | J37: X-ray | K37: 45718 | L37: Gushchin et al., PNAS, 2013 | N37: 4HYJ | O37: EVNLLVLATQYMFWVGFVGMAAGTLYFLVERNSLAPEYRSTATVAALVTFVAAIHYYFMKDAVGTSGLLSEIDGFPTEIRYIDWLVTTPLLLVKFPLLLGRLGRPLLTKLVIADVIMIVGGYIGESSINIAGGFTQLGLWSYLIGCFAWIYIIYLLFTNVTKAAENKPAPIRDALLKMRLFILIGWAIYPIGYAVTLFAPGVEIQLVRELIYNFADLTNKVGFGLIAFFAVKTMSS | P37: B1YFV8 | Q37: 236.0 | R37: EVNLLVLATQYMFWVGFVGMAAGTLYFLVERNSLAPEYRSTATVAALVTFVAAIHYYFMKDAVGTSGLLSEIDGFPTEIRYIDWLVTTPLLLVKFPLLLGRLGRPLLTKLVIADVIMIVGGYIGESSINIAGGFTQLGLWSYLIGCFAWIYIIYLLFTNVTKAAENKPAPIRDALLKMRLFILIGWAIYPIGYAVTLFAPGVEIQLVRELIYNFADLTNKVGFGLIAFFAVKTMSS | U37: ESR | V37: ESR | W37: O82a52e1d2 | X37: TRUE | Y37: ESR | Z37: ESR | AA37: Proton pump | AB37: ESR_Exiguobacterium artemiae
A38: 46 | B38: include | C38: MacR | E38: Candidatus Actinomarina minuta | F38: Bacteria | G38: outward proton pump | H38: outward proton pump | I38: 7AVN | J38: X-ray | K38: 45809 | L38: unpublished??? | N38: 7AVN | O38: MEELTYRLFMVATVGMLAGTVFLLASSREVKPEHRRGVYISALVCGIAWYHYQKMGASWESGSYDTGLRYVDWVLTVPLMFVEVLAVTRKGAAYNEAVRNWGIAATVMIGAGYYGETSAAGSNEYWTGFVIAMATYVWLMRNLQAEGEGLKGDQAVAFENIKNLILVGWIIYPLGYIAPVVGDFDAIREVLYTIADIINVGLGVLVLQMARVQSGE | P38: S5DM51 | Q38: 216.0 | R38: MEELTYRLFMVATVGMLAGTVFLLASSREVKPEHRRGVYISALVCGIAWYHYQKMGASWESGSYDTGLRYVDWVLTVPLMFVEVLAVTRKGAAYNEAVRNWGIAATVMIGAGYYGETSAAGSNEYWTGFVIAMATYVWLMRNLQAEGEGLKGDQAVAFENIKNLILVGWIIYPLGYIAPVVGDFDAIREVLYTIADIINVGLGVLVLQMARVQSGE | U38: MacR | V38: MacR | W38: Ob29057596 | X38: TRUE | Y38: MacR | Z38: MacR | AA38: Proton pump | AB38: MacR_Candidatus Actinomarina minuta
A39: 47 | B39: include | C39: VirR DTS | E39: Phaeocystis globosa virus 12T | F39: Virus | G39: outward proton pump | H39: outward proton pump | I39: 6JO0 | J39: X-ray | K39: 45839 | L39: Needham et al., PNAS., 2019 | N39: 6JO0 | O39: ENSFIVKNTMIFSFLIQIITLIIGIFAQFIKVPRHKYILKDALLLENIVQFIEAIFYLWFIYFYKENVDKIDIAKYRYYDWFLTTPTMILSVIIYFHYNNSSKKIYYNMITFFKQDFRKILELWFYNFNMLIIGYLQEINIISILLSTLIGFYFFGLLFYKMFKYYVVQNKKNYLLFFLMFFIWGLYGIAALFNYKFKNAFYNILDIFSKNFFGLFLAYLVFTG | P39: G8DI69 | Q39: 224.0 | R39: ENSFIVKNTMIFSFLIQIITLIIGIFAQFIKVPRHKYILKDALLLENIVQFIEAIFYLWFIYFYKENVDKIDIAKYRYYDWFLTTPTMILSVIIYFHYNNSSKKIYYNMITFFKQDFRKILELWFYNFNMLIIGYLQEINIISILLSTLIGFYFFGLLFYKMFKYYVVQNKKNYLLFFLMFFIWGLYGIAALFNYKFKNAFYNILDIFSKNFFGLFLAYLVFTG | U39: VirR DTS | V39: VirR_DTS | W39: Oac2e063ab | X39: TRUE | Y39: VirR DTS | Z39: VirR | AA39: Proton pump | AB39: VirR_DTS_Phaeocystis globosa virus 12T
A40: 48 | B40: include | C40: CyR N2098R | D40: cyanorhodopsin N2098R | E40: Calothrix sp. NIES-2098 | F40: Bacteria | G40: outward proton pump | H40: outward proton pump | I40: 6LM0 | J40: X-ray | K40: 45840 | L40: Hasegawa et al., Sci Rep., 2020 | N40: 6LM0 | O40: SGMTQFWLWVGFIGMVIGCIYFGMKASAMRRREGMEFPLESFFITLWAAALYLTMILGETVTPINGQTVFWGRYIDWVVTTPLLLMELGVIAGLRPKLIAGVMGADIFMIVTGFIGAVEAPPYNYLWWLISTGSFLAILGSLLTEYSASAKRRNGRINSLFQTLRNILIVLWICYPIVWILGAEGFHVISVGWETLCYSVLDVCAKVGFGFVVVSAGNETLAQASNSDRIMETVHSYMQSEE | P40: A0A1Z4FUT4 | Q40: 242.0 | R40: SGMTQFWLWVGFIGMVIGCIYFGMKASAMRRREGMEFPLESFFITLWAAALYLTMILGETVTPINGQTVFWGRYIDWVVTTPLLLMELGVIAGLRPKLIAGVMGADIFMIVTGFIGAVEAPPYNYLWWLISTGSFLAILGSLLTEYSASAKRRNGRINSLFQTLRNILIVLWICYPIVWILGAEGFHVISVGWETLCYSVLDVCAKVGFGFVVVSAGNETLAQASNSDRIMETVHSYMQSEE | U40: CyR N2098R | V40: CyR_N2098R | W40: O44e64517b | X40: TRUE | Y40: cyanorhodopsin N2098R | Z40: cyR-N2098R | AA40: Proton pump | AB40: CyR_N2098R_Calothrix sp. NIES-2098
...

Sheet mo_exp_identity_UTedited6
A1: no | B1: remove | C1: opsin name | D1: other name | E1: source (species) | F1: Rhodopsin Type (Microbial) | G1: class (function) | H1: molecular_function | I1: PDB ID | J1: method | K1: resolution | L1: reference | M1: sequence | N1: pdb_id | O1: structure_sequence | P1: uniprot_id | Q1: length | R1: seq | S1: end | T1: start | U1: name | V1: protein | W1: protein_id | X1: experimentally_determined | Y1: display_name | Z1: short_name | AA1: molecular_function_normalized | AB1: full_protein
A2: 1 | B2: recommeded to remove | C2: BPR(duplicated with HOT75BPR-D97N) | E2: Uncultured marine bacteria (labeled 'Blue') | F2: Bacteria | H2: outward proton pump | M2: MGKLLLILGSAIALPSFAAAGGDLDISDTVGVSFWLVTAGMLAATVFFFVERDQVSAKWKTSLTVSGLITGIAFWHYLYMRGVWIDTGDTPTVFRYIDWLLTVPLQVVEFYLILAACTSVAASLFKKLLAGSLVMLGAGFAGEAGLAPVLPAFIIGMAGWLYMIYELYMGEGKAAVSTASPAVNSAYNAMMMIIVVGWAIYPAGYAAGYLMGGEGVYASNLNLIYNLADFVNKILFGLIIWNVAVKESSNA | N2: 4KLY | O2: GDLDISDTVGVSFWLVTAGLAATVFFFVERDQVSAKWKTSLTVSGLITGIAFWHYLYRGVWIDTGDTPTVFRYINWLLTVPLQVVEFYLILAACTSVAASLFKKLLAGSLVLGAGFAGEAGLAPVLPAFIIGAGWLYIYELYGEGKAAVSTASPAVNSAYNAIIVVGWAIYPAGYAAGYLVYASNLNLIYNLADFVNKILFGLIIWNVAVKESSNALEHHH | P2: Q9AFF7 | Q2: 221.0 | R2: GDLDISDTVGVSFWLVTAGLAATVFFFVERDQVSAKWKTSLTVSGLITGIAFWHYLYRGVWIDTGDTPTVFRYINWLLTVPLQVVEFYLILAACTSVAASLFKKLLAGSLVLGAGFAGEAGLAPVLPAFIIGAGWLYIYELYGEGKAAVSTASPAVNSAYNAIIVVGWAIYPAGYAAGYLVYASNLNLIYNLADFVNKILFGLIIWNVAVKESSNALEHHH | U2: Blue Proteorhodopsin | V2: Blue_Proteorhodopsin | W2: Ob26394f0f | X2: TRUE | Y2: BPR | Z2: BPR | AA2: Proton pump | AB2: Blue_Proteorhodopsin_Uncultured marine bacteria (labeled 'Blue')
A3: 2 | B3: include | C3: CrChR1 | E3: Chlamydomonas reinhardtii | F3: Eukaryota | G3: cation channel | H3: non-selective cation channel | M3: MSRRPWLLALALAVALAAGSAGASTGSDATVPVATQDGPDYVFHRAHERMLFQTSYTLENNGSVICIPNNGQCFCLAWLKSNGTNAEKLAANILQWITFALSALCLMFYGYQTWKSTCGWEEIYVATIEMIKFIIEYFHEFDEPAVIYSSNGNKTVWLRYAEWLLTCPVILIHLSNLTGLANDYNKRTMGLLVSDIGTIVWGTTAALSKGYVRVIFFLMGLCYGIYTFFNAAKVYIEAYHTVPKGICRDLVRYLAWLYFCSWAMFPVLFLLGPEGFGHINQFNSAIAHAILDLASKNAWSMMGHFLRVKIHEHILLYGDIRKKQKVNVAGQEMEVETMVHEEDDETQKVPTAKYANRDSFIIMRDRLKEKGFETRASLDGDPNGDAEANAAAGGKPGMEMGKMTGMGMGMGAGMGMATIDSGRVILAVPDISMVDFFREQFARLPVPYELVPALGAENTLQLVQQAQSLGGCDFVLMHPEFLRDRSPTGLLPRLKMGGQRAAAFGWAAIGPMRDLIEGSGVDGWLEGPSFGAGINQQALVALINRMQQAKKMGMMGGMGMGMGGGMGMGMGMGMGMAPSMNAGMTGGMGGASMGGAVMGMGMGMQPMQQAMPAMSPMMTQQPSMMSQPSAMSAGGAMQAMGGVMPSPAPGGRVGTNPLFGSAPSPLSSQPGISPGMATPPAATAAPAAGGSEAEMLQQLMSEINRLKNELGE | N3: 3UG9 | O3: RMLFQTSYTLENNGSVICIPNNGQCFCLAWLKSNGTNAEKLAANILQWITFALSALCLMFYCGWEEIYVATIEMIKFIIEYFHEFDEPAVIYSSNGNKTVWLRYAEWLLTCPVILIHLSNLTGLANDYNKRTMGLLVSDIGTIVWGTTAALSKGYVRVIFFLMGLCYGIYTFFNAAKVYIEAYHTVPKGRCRQVVTGMAWLFFVSWGMFPILFILGPEGFGVLSVYGSTVGHTIIDLMSKNCWGLLGHYLRVLIHEHILIHGDIRKTTKLIEVETLVEDE | P3: Q93WP2,Q8RUT8 | Q3: 280.0 | R3: RMLFQTSYTLENNGSVICIPNNGQCFCLAWLKSNGTNAEKLAANILQWITFALSALCLMFYCGWEEIYVATIEMIKFIIEYFHEFDEPAVIYSSNGNKTVWLRYAEWLLTCPVILIHLSNLTGLANDYNKRTMGLLVSDIGTIVWGTTAALSKGYVRVIFFLMGLCYGIYTFFNAAKVYIEAYHTVPKGRCRQVVTGMAWLFFVSWGMFPILFILGPEGFGVLSVYGSTVGHTIIDLMSKNCWGLLGHYLRVLIHEHILIHGDIRKTTKLIEVETLVEDE | U3: Chlamydomonas reinhardtii Channelrhodopsin-1 | V3: Chlamydomonas_reinhardtii_Channelrhodopsin_1 | W3: O5537c97da | X3: TRUE | Y3: CrChR1 | Z3: CrChR1 | AA3: Cation channel | AB3: Chlamydomonas_reinhardtii_Channelrhodopsin_1_Chlamydomonas reinhardtii
A4: 3 | B4: recommeded to remove | C4: CyR (duplicated with CyR N2098R) | E4: Cyanobacteria (unspecified) | F4: Bacteria | H4: outward proton pump | N4: 6LM0 | O4: SGMTQFWLWVGFIGMVIGCIYFGMKASAMRRREGMEFPLESFFITLWAAALYLTMILGETVTPINGQTVFWGRYIDWVVTTPLLLMELGVIAGLRPKLIAGVMGADIFMIVTGFIGAVEAPPYNYLWWLISTGSFLAILGSLLTEYSASAKRRNGRINSLFQTLRNILIVLWICYPIVWILGAEGFHVISVGWETLCYSVLDVCAKVGFGFVVVSAGNETLAQASNSDRIMETVHSYMQSEE | P4: A0A1Z4FUT4 | Q4: 242.0 | R4: SGMTQFWLWVGFIGMVIGCIYFGMKASAMRRREGMEFPLESFFITLWAAALYLTMILGETVTPINGQTVFWGRYIDWVVTTPLLLMELGVIAGLRPKLIAGVMGADIFMIVTGFIGAVEAPPYNYLWWLISTGSFLAILGSLLTEYSASAKRRNGRINSLFQTLRNILIVLWICYPIVWILGAEGFHVISVGWETLCYSVLDVCAKVGFGFVVVSAGNETLAQASNSDRIMETVHSYMQSEE | U4: Cyanorhodopsin | V4: Cyanorhodopsin | W4: Oba67b967a | X4: TRUE | Y4: CyR | Z4: CyR | AA4: Proton pump | AB4: Cyanorhodopsin_Cyanobacteria (unspecified)
A5: 4 | B5: include | C5: FR | E5: Fulvimarina pelagi | F5: Bacteria | G5: inward chloride pump | H5: inward chloride pump | M5: MQDTELFADQLGNIENLVSLTVGQYTMGSLILMVSYGAHFAFVLYFLMTSLQLAPRYRIVPIMSAIVMVSAGLSLLREFNAWEQSYEFVEGMYQPLAENSTFTNAYRYGNWTITVPILLTQLPLAFGLLRPELHVRAARMCIPALLMIWTGLVGQFGETGNYLRLNVWGVISTIFFVWLIIEVRGVISRAIAMGPAELAAWPKNIWWFFLAFWGLYPIAYALPQLGHTGDIVVIRQLLYSIADVFSKLVYGIILSRYVLRRSALEGYKPAIEALSRTPVDLSMSKNGGAGYGDGDR | Q5: 296.0 | R5: MQDTELFADQLGNIENLVSLTVGQYTMGSLILMVSYGAHFAFVLYFLMTSLQLAPRYRIVPIMSAIVMVSAGLSLLREFNAWEQSYEFVEGMYQPLAENSTFTNAYRYGNWTITVPILLTQLPLAFGLLRPELHVRAARMCIPALLMIWTGLVGQFGETGNYLRLNVWGVISTIFFVWLIIEVRGVISRAIAMGPAELAAWPKNIWWFFLAFWGLYPIAYALPQLGHTGDIVVIRQLLYSIADVFSKLVYGIILSRYVLRRSALEGYKPAIEALSRTPVDLSMSKNGGAGYGDGDR | U5: Fulvimarina pelagi Chloride pump | V5: Fulvimarina_pelagi_Chloride_pump | W5: Of45b61cb1 | X5: FALSE | Y5: FR | Z5: FR | AA5: Chloride pump | AB5: Fulvimarina_pelagi_Chloride_pump_Fulvimarina pelagi
A6: 5 | B6: include | C6: GPR | E6: Marine proteobacteria (labeled 'Green') | F6: Bacteria | G6: outward proton pump | H6: outward proton pump | M6: MKLLLILGSVIALPTFAAGGGDLDASDYTGVSFWLVTAALLASTVFFFVERDRVSAKWKTSLTVSGLVTGIAFWHYMYMRGVWIETGDSPTVFRYIDWLLTVPLLICEFYLILAAATNVAGSLFKKLLVGSLVMLVFGYMGEAGIMAAWPAFIIGCLAWVYMIYELWAGEGKSACNTASPAVQSAYNTMMYIIIFGWAIYPVGYFTGYLMGDGGSALNLNLIYNLADFVNKILFGLIIWNVAVKESSNA | N6: 2L6X | O6: MGGGDLDASDYTGVSFWLVTAALLASTVFFFVERDRVSAKWKTSLTVSGLVTGIAFWHYMYMRGVWIETGDSPTVFRYIDWLLTVPLLICEFYLILAAATNVAGSLFKKLLVGSLVMLVFGYMGEAGIMAAWPAFIIGCLAWVYMIYELWAGEGKSACNTASPAVQSAYNTMMYIIIFGWAIYPVGYFTGYLMGDGGSALNLNLIYNLADFVNKILFGLIIWNVAVKESSNAPGG | P6: Q9F7P4 | Q6: 235.0 | R6: MGGGDLDASDYTGVSFWLVTAALLASTVFFFVERDRVSAKWKTSLTVSGLVTGIAFWHYMYMRGVWIETGDSPTVFRYIDWLLTVPLLICEFYLILAAATNVAGSLFKKLLVGSLVMLVFGYMGEAGIMAAWPAFIIGCLAWVYMIYELWAGEGKSACNTASPAVQSAYNTMMYIIIFGWAIYPVGYFTGYLMGDGGSALNLNLIYNLADFVNKILFGLIIWNVAVKESSNAPGG | U6: Green Proteorhodopsin | V6: Green_Proteorhodopsin | W6: O7b6459cd7 | X6: TRUE | Y6: GPR | Z6: GPR | AA6: Proton pump | AB6: Green_Proteorhodopsin_Marine proteobacteria (labeled 'Green')
A7: 6 | B7: include | C7: GtACR2 | E7: Guillardia theta | F7: Eukaryota | G7: anion channel | H7: non-selective anion channel | M7: MASQVVYGEWASTHTECYNMSRIDSTFVSLLQLVWAVVSGCQTIFMISRAPKVPWESVYLPFVESITYALASTGNGTLQMRDGRFFPWSRMASWLCTCPIMLGQISNMALVKYKSIPLNPIAQAASIIRVVMGITATISPAEYMKWLFFFFGATCLVFEYSVVFTIFQVGLYGFESVGTPLAQKVVVRIKMLRLIFFIAWTMFPIVWLISPTGVCVIHENVSAILYLLADGLCKNTYGVILWSTAWGVLEGKWDPACLPGQEKPEADDPFGLNHEKNAPPNDEVNIRMFGR | Q7: 291.0 | R7: MASQVVYGEWASTHTECYNMSRIDSTFVSLLQLVWAVVSGCQTIFMISRAPKVPWESVYLPFVESITYALASTGNGTLQMRDGRFFPWSRMASWLCTCPIMLGQISNMALVKYKSIPLNPIAQAASIIRVVMGITATISPAEYMKWLFFFFGATCLVFEYSVVFTIFQVGLYGFESVGTPLAQKVVVRIKMLRLIFFIAWTMFPIVWLISPTGVCVIHENVSAILYLLADGLCKNTYGVILWSTAWGVLEGKWDPACLPGQEKPEADDPFGLNHEKNAPPNDEVNIRMFGR | U7: Guillardia theta Anion Channelrhodopsin-2 | V7: Guillardia_theta_Anion_Channelrhodopsin_2 | W7: O9d96fda5e | X7: FALSE | Y7: GtACR2 | Z7: GtACR2 | AA7: Anion channel | AB7: Guillardia_theta_Anion_Channelrhodopsin_2_Guillardia theta
A8: 7 | B8: recommeded to remove | C8: HmBRI | E8: Haloarcula marismortui | F8: Archaea | G8: outward proton pump | H8: outward proton pump | M8: MPAPGSEGIWLWLGTAGMFLGMLYFIARGWGETDGRRQKFYIATILITAIAFVNYLAMALGFGLTFIEFGGEQHPIYWARYTDWLFTTPLLLYDLGLLAGADRNTIYSLVSLDVLMIGTGVVATLSAGSGVLSAGAERLVWWGISTAFLLVLLYFLFSSLSGRVANLPSDTRSTFKTLRNLVTVVWLVYPVWWLVGSEGLGLVGIGIETAGFMVIDLVAKVGFGIILLRSHGVLDGAAETTGTGATPADD | N8: 4PXK | O8: APGSEGIWLWLGTAGMFLGMLYFIARGWGETDGRRQKFYIATILITAIAFVNYLAMALGFGLTFIEFGGEQHPIYWARYTDWLFTTPLLLYNLGLLAGADRNTIYSLVSLDVLMIGTGVVATLSAGSGVLSAGAERLVWWGISTAFLLVLLYFLFSSLSGRVANLPSDTRSTFKTLRNLVTVVWLVYPVWWLVGSEGLGLVGIGIETAGFMVIDLVAKVGFGIILLRSHGVLDGAA | P8: Q5UXY6 | Q8: 236.0 | R8: APGSEGIWLWLGTAGMFLGMLYFIARGWGETDGRRQKFYIATILITAIAFVNYLAMALGFGLTFIEFGGEQHPIYWARYTDWLFTTPLLLYNLGLLAGADRNTIYSLVSLDVLMIGTGVVATLSAGSGVLSAGAERLVWWGISTAFLLVLLYFLFSSLSGRVANLPSDTRSTFKTLRNLVTVVWLVYPVWWLVGSEGLGLVGIGIETAGFMVIDLVAKVGFGIILLRSHGVLDGAA | U8: Haloarcula marismortui Bacteriorhodopsin I | V8: Haloarcula_marismortui_Bacteriorhodopsin_I | W8: Ob81194c9e | X8: TRUE | Y8: HmBRI | Z8: HmBRI | AA8: Proton pump | AB8: Haloarcula_marismortui_Bacteriorhodopsin_I_Haloarcula marismortui
A9: 8 | B9: recommeded to remove | C9: HmBRII | E9: Haloarcula marismortui | F9: Archaea | G9: outward proton pump | H9: outward proton pump | M9: MLPLQVSSLGVEGEGIWLALGTVGMLLGMVYFMAKGWDVQDPEQEEFYVITILIAGIAASSYLSMFFGFGLTEVELVNGRVIDVYWARYADWLFTTPLLLLDIGLLAGASNRDMASLITIDAFMIVTGLAATLMKVPVARYAFWTISTIAMLFVLYYLVVVVGEAASDASEEAQSTFNVLRNIILVAWAIYPVAWLVGTEGLGLVGLFGETLLFMILDLTAKIGFGFILLRSRAIVGGDSAPTPSAEAAD | Q9: 250.0 | R9: MLPLQVSSLGVEGEGIWLALGTVGMLLGMVYFMAKGWDVQDPEQEEFYVITILIAGIAASSYLSMFFGFGLTEVELVNGRVIDVYWARYADWLFTTPLLLLDIGLLAGASNRDMASLITIDAFMIVTGLAATLMKVPVARYAFWTISTIAMLFVLYYLVVVVGEAASDASEEAQSTFNVLRNIILVAWAIYPVAWLVGTEGLGLVGLFGETLLFMILDLTAKIGFGFILLRSRAIVGGDSAPTPSAEAAD | U9: Haloarcula marismortui Bacteriorhodopsin II | V9: Haloarcula_marismortui_Bacteriorhodopsin_II | W9: Ob946aa20c | X9: FALSE | Y9: HmBRII | Z9: HmBRII | AA9: Proton pump | AB9: Haloarcula_marismortui_Bacteriorhodopsin_II_Haloarcula marismortui
A10: 9 | B10: include | C10: HmHR | E10: Haloarcula marismortui | F10: Archaea | G10: inward chloride pump | H10: inward chloride pump | M10: MTAASTTATTVLQATQSDVLQEIQSNFLLNSSIWVNIALAGVVILLFVAMGRDLESPRAKLIWVATMLVPLVSISSYAGLASGLTVGFLQMPPGHALAGQEVLSPWGRYLTWTFSTPMILLALGLLADTDIASLFTAITMDIGMCVTGLAAALITSSHLLRWVFYGISCAFFVAVLYVLLVQWPADAEAAGTSEIFGTLKILTVVLWLGYPILWALGSEGVALLSVGVTSWGYSGLDILAKYVFAFLLLRWVAANEGTVSGSGMGIGSGGATPADD | Q10: 276.0 | R10: MTAASTTATTVLQATQSDVLQEIQSNFLLNSSIWVNIALAGVVILLFVAMGRDLESPRAKLIWVATMLVPLVSISSYAGLASGLTVGFLQMPPGHALAGQEVLSPWGRYLTWTFSTPMILLALGLLADTDIASLFTAITMDIGMCVTGLAAALITSSHLLRWVFYGISCAFFVAVLYVLLVQWPADAEAAGTSEIFGTLKILTVVLWLGYPILWALGSEGVALLSVGVTSWGYSGLDILAKYVFAFLLLRWVAANEGTVSGSGMGIGSGGATPADD | U10: Haloarcula marismortui Halorhodopsin | V10: Haloarcula_marismortui_Halorhodopsin | W10: O017a1ade5 | X10: FALSE | Y10: HmHR | Z10: HmHR | AA10: Chloride pump | AB10: Haloarcula_marismortui_Halorhodopsin_Haloarcula marismortui
A11: 10 | B11: include | C11: HmSRI | E11: Haloarcula marismortui | F11: Archaea | G11: regulation of transducer | H11: regulation of transducer | M11: MDAVSVVYGITAAGFAVGVAIVGFLYASLEGSDERPILAALALIPGVAGISYVAMVFGIGTVTIGETTLVGFRYLDWVVTTPLLVGFIGYTAGASRRAIFGVMAADALMILAGVGAVVAAGTLKWALFGVSAVFHISLFAYLYLIFPRSVPDDPQRIGLFSLLKNHVGLLWIAYPLVWLAGPEGLGFATYVGVSITYAFLDLLAKVPYVYFFYARRQVFATKLLRDSGDTTVTPAD | Q11: 236.0 | R11: MDAVSVVYGITAAGFAVGVAIVGFLYASLEGSDERPILAALALIPGVAGISYVAMVFGIGTVTIGETTLVGFRYLDWVVTTPLLVGFIGYTAGASRRAIFGVMAADALMILAGVGAVVAAGTLKWALFGVSAVFHISLFAYLYLIFPRSVPDDPQRIGLFSLLKNHVGLLWIAYPLVWLAGPEGLGFATYVGVSITYAFLDLLAKVPYVYFFYARRQVFATKLLRDSGDTTVTPAD | U11: Haloarcula marismortui Sensory Rhodopsin I | V11: Haloarcula_marismortui_Sensory_Rhodopsin_I | W11: O132494edf | X11: FALSE | Y11: HmSRI | Z11: HmSRI | AA11: Phototaxis | AB11: Haloarcula_marismortui_Sensory_Rhodopsin_I_Haloarcula marismortui
A12: 11 | B12: include | C12: HmSRII | E12: Haloarcula marismortui | F12: Archaea | G12: regulation of transducer | H12: regulation of transducer | M12: MATITTWFTLGLLGELLGTAVLAYGYTLVPEETRKRYLLLIAIPGIAIVAYALMALGFGSIQSEGHAVYVVRYVDWLLTTPLNVWFLALLAGASREDTVKLVVLQALTIVFGFAGAVTPSPVSYALFAVGGALFGGVIYLLYRNIAVAAKSTLSDIEVSLYRTLRNFVVVLWLVYPVVWLLGAAGVGLMDVETATLVVVYLDVVTKVGFGVIALLAMIDLGSAGETAEEPTAVAGD | Q12: 236.0 | R12: MATITTWFTLGLLGELLGTAVLAYGYTLVPEETRKRYLLLIAIPGIAIVAYALMALGFGSIQSEGHAVYVVRYVDWLLTTPLNVWFLALLAGASREDTVKLVVLQALTIVFGFAGAVTPSPVSYALFAVGGALFGGVIYLLYRNIAVAAKSTLSDIEVSLYRTLRNFVVVLWLVYPVVWLLGAAGVGLMDVETATLVVVYLDVVTKVGFGVIALLAMIDLGSAGETAEEPTAVAGD | U12: Haloarcula marismortui Sensory Rhodopsin II | V12: Haloarcula_marismortui_Sensory_Rhodopsin_II | W12: O91af35bb0 | X12: FALSE | Y12: HmSRII | Z12: HmSRII | AA12: Phototaxis | AB12: Haloarcula_marismortui_Sensory_Rhodopsin_II_Haloarcula marismortui
A13: 12 | B13: include | C13: HmSRIII | E13: Haloarcula marismortui | F13: Archaea | G13: regulation of transducer | H13: regulation of transducer | M13: MAQEIVWYGAGAGAFFVSAVVFVWFAATRGNIRSSFYYLPPIHTSVAGAAYVAMALIAGGQLGDTVSITTLRFADWIVSTPIITYYLARLAGVDTQTRRLAVAANVVMIGVGYGFVSMSGSLRWIAFAVSTVAFIGLLYLYIKTFARKINAATASVRSLFQSLRDLTVVTWSLYPVVYFLGPLGTGIIQAPDLNFLVAVLDTIAKVGFMSILLVRYNSVETFVDSWSVAPAK | Q13: 232.0 | R13: MAQEIVWYGAGAGAFFVSAVVFVWFAATRGNIRSSFYYLPPIHTSVAGAAYVAMALIAGGQLGDTVSITTLRFADWIVSTPIITYYLARLAGVDTQTRRLAVAANVVMIGVGYGFVSMSGSLRWIAFAVSTVAFIGLLYLYIKTFARKINAATASVRSLFQSLRDLTVVTWSLYPVVYFLGPLGTGIIQAPDLNFLVAVLDTIAKVGFMSILLVRYNSVETFVDSWSVAPAK | U13: Haloarcula marismortui Sensory Rhodopsin III | V13: Haloarcula_marismortui_Sensory_Rhodopsin_III | W13: O9aaaef0fd | X13: FALSE | Y13: HmSRIII | Z13: HmSRIII | AA13: Phototaxis | AB13: Haloarcula_marismortui_Sensory_Rhodopsin_III_Haloarcula marismortui
A14: 13 | B14: include | C14: HsSRI | E14: Halobacterium salinarum | F14: Archaea | G14: regulation of transducer | H14: regulation of transducer | M14: MDAVATAYLGGAVALIVGVAFVWLLYRSLDGSPHQSALAPLAIIPVFAGLSYVGMAYDIGTVIVNGNQIVGLRYIDWLVTTPILVGYVGYAAGASRRSIIGVMVADALMIAVGAGAVVTDGTLKWALFGVSSIFHLSLFAYLYVIFPRVVPDVPEQIGLFNLLKNHIGLLWLAYPLVWLFGPAGIGEATAAGVALTYVFLDVLAKVPYVYFFYARRRVFMHSESPPAPEQATVEATAAD | Q14: 239.0 | R14: MDAVATAYLGGAVALIVGVAFVWLLYRSLDGSPHQSALAPLAIIPVFAGLSYVGMAYDIGTVIVNGNQIVGLRYIDWLVTTPILVGYVGYAAGASRRSIIGVMVADALMIAVGAGAVVTDGTLKWALFGVSSIFHLSLFAYLYVIFPRVVPDVPEQIGLFNLLKNHIGLLWLAYPLVWLFGPAGIGEATAAGVALTYVFLDVLAKVPYVYFFYARRRVFMHSESPPAPEQATVEATAAD | U14: Halobacterium salinarum Sensory Rhodopsin I | V14: Halobacterium_salinarum_Sensory_Rhodopsin_I | W14: O67713bee1 | X14: FALSE | Y14: HsSRI | Z14: HsSRI | AA14: Phototaxis | AB14: Halobacterium_salinarum_Sensory_Rhodopsin_I_Halobacterium salinarum
A15: 14 | B15: recommeded to remove | C15: HxAR | E15: Halorubrum xinjiangense | F15: Archaea | G15: outward proton pump | H15: outward proton pump | M15: MDPIALQAGYDLLGDGRPETLWLGIGTLLMLIGTFYFIVKGWGVTDKEAREYYSITILVPGIASAAYLSMFFGIGLTEVQVGSEMLDIYYARYADWLFTTPLLLLDLALLAKVDRVSIGTLVGVDALMIVTGLIGALSHTPLARYTWWLFSTICMIVVLYFLATSLRAAAKERGPEVASTFNTLTALVLVLWTAYPILWIVGTEGAGVVGLGIETLLFMVLDVTAKVGFGFILLRSRAILGDTQAPEPSAGADAQAAD | Q15: 258.0 | R15: MDPIALQAGYDLLGDGRPETLWLGIGTLLMLIGTFYFIVKGWGVTDKEAREYYSITILVPGIASAAYLSMFFGIGLTEVQVGSEMLDIYYARYADWLFTTPLLLLDLALLAKVDRVSIGTLVGVDALMIVTGLIGALSHTPLARYTWWLFSTICMIVVLYFLATSLRAAAKERGPEVASTFNTLTALVLVLWTAYPILWIVGTEGAGVVGLGIETLLFMVLDVTAKVGFGFILLRSRAILGDTQAPEPSAGADAQAAD | U15: Halorubrum xinjiangense Archaerhodopsin | V15: Halorubrum_xinjiangense_Archaerhodopsin | W15: O272ca584d | X15: FALSE | Y15: HxAR | Z15: HxAR | AA15: Proton pump | AB15: Halorubrum_xinjiangense_Archaerhodopsin_Halorubrum xinjiangense
A16: 15 | B16: include | C16: KR1 | E16: Krokinobacter eikastus | F16: Bacteria | G16: outward proton pump | H16: outward proton pump | M16: MKFLLLLLADPTKLDPSDYVGFTFFVGAMAMMAASAFFFLSLNQFNKKWRTSVLVSGLITFIAAVHYWYMRDYWFAIQESPTFFRYVDWVLTVPLMCVEFYLILKVAGAKPALMWKLILFSVIMLVTGYFGEAVFQDQAALWGAISGAAYFYIVYEIWLGSAKKLAVAAGGDILKAHKILCWFVLVGWAIYPLGYMLGTDGWYTSILGKGSVDVAYNIADAINKIGFGLVIYALAVKKNEVDVV | Q16: 244.0 | R16: MKFLLLLLADPTKLDPSDYVGFTFFVGAMAMMAASAFFFLSLNQFNKKWRTSVLVSGLITFIAAVHYWYMRDYWFAIQESPTFFRYVDWVLTVPLMCVEFYLILKVAGAKPALMWKLILFSVIMLVTGYFGEAVFQDQAALWGAISGAAYFYIVYEIWLGSAKKLAVAAGGDILKAHKILCWFVLVGWAIYPLGYMLGTDGWYTSILGKGSVDVAYNIADAINKIGFGLVIYALAVKKNEVDVV | U16: Krokinobacter Rhodopsin-1 | V16: Krokinobacter_Rhodopsin_1 | W16: O24730b7f1 | X16: FALSE | Y16: KR1 | Z16: KR1 | AA16: Proton pump | AB16: Krokinobacter_Rhodopsin_1_Krokinobacter
A17: 16 | B17: recommeded to remove | C17: Med12 (duplicated with Med12BPR) | E17: Halobacterium (unspecified) | F17: Archaea | G17: outward proton pump | H17: outward proton pump | N17: 4JQ6 | O17: DYVGISFWLAAAIMLASTVFFFVERSDVPVKWKTSLTVAGLVTGVAFWHYLYMRGVWIYAGETPTVFRYIDWLITVPLQIIEFYLIIAAAVFWKLLIASLVMLIGGFIGEAGLGDVVVWWIVGMIAWLYIIYEIFLGAASQQAFNTIKWIVTVGWAIYPIGYAWGYFGDGLNEDALNIVYNLADLINKAAFGLAIWAAAMKDK | P17: Q4PP54 | Q17: 203.0 | R17: DYVGISFWLAAAIMLASTVFFFVERSDVPVKWKTSLTVAGLVTGVAFWHYLYMRGVWIYAGETPTVFRYIDWLITVPLQIIEFYLIIAAAVFWKLLIASLVMLIGGFIGEAGLGDVVVWWIVGMIAWLYIIYEIFLGAASQQAFNTIKWIVTVGWAIYPIGYAWGYFGDGLNEDALNIVYNLADLINKAAFGLAIWAAAMKDK | U17: Medarhodopsin-12 | V17: Medarhodopsin_12 | W17: Od8d044f37 | X17: TRUE | Y17: Med12 | Z17: Med12 | AA17: Proton pump | AB17: Medarhodopsin_12_Halobacterium (unspecified)
A18: 17 | B18: include | C18: NR | E18: Neurospora crassa | F18: Eukaryota | G18: outward proton pump | H18: outward proton pump | M18: MIHPEQVADMLRPTTSTTSSHVPGPVPTVVPTPTEYQTLGETGHRTLWVTFALMVLSSGIFALLSWNVPTSKRLFHVITTLITVVASLSYFAMATGHATTFNCDTAWDHHKHVPDTSHQVCRQVFWGRYVDWALTTPLLLLELCLLAGVDGAHTLMAIVADVIMVLCGLFAALGEGGNTAQKWGWYTIGCFSYLFVIWHVALHGSRTVTAKGRGVSRLFTGLAVFALLLWTAYPIIWGIAGGARRTNVDTEILIYTVLDLLAKPVFGFWLLLSHRAMPETNIDLPGYWSHGLATEGRIRIGEED | Q18: 304.0 | R18: MIHPEQVADMLRPTTSTTSSHVPGPVPTVVPTPTEYQTLGETGHRTLWVTFALMVLSSGIFALLSWNVPTSKRLFHVITTLITVVASLSYFAMATGHATTFNCDTAWDHHKHVPDTSHQVCRQVFWGRYVDWALTTPLLLLELCLLAGVDGAHTLMAIVADVIMVLCGLFAALGEGGNTAQKWGWYTIGCFSYLFVIWHVALHGSRTVTAKGRGVSRLFTGLAVFALLLWTAYPIIWGIAGGARRTNVDTEILIYTVLDLLAKPVFGFWLLLSHRAMPETNIDLPGYWSHGLATEGRIRIGEED | U18: Neurospora Rhodopsin | V18: Neurospora_Rhodopsin | W18: Oa33e502bd | X18: FALSE | Y18: NR | Z18: NR | AA18: Proton pump | AB18: Neurospora_Rhodopsin_Neurospora
A19: 18 | B19: include | C19: NdR1 | E19: Nonlabens dokdonensis | F19: Bacteria | G19: outward proton pump | H19: outward proton pump | M19: MNFLLSTLEVAKMATDDYVGFTFFIGSMAMMAASAFFFLSLSQFDNKWRTSVLVSGLITFIAAVHYFYMRDYYAATDSSPTFFRYVDWTLTVPLMCVEFYLILKVAGAKLGLMWKLIFWSVVMLVTGYFGEVIALGNPTMQWVWGLVSGIAYFIIVYMIWFGEAKKLATSAGGAVLKAHNILCWFVLVGWAIYPLGYILGTEGGLFGLQLVEDPKAAQEAMDVVYNIGDAINKIGFGLVIYSLAVTSSKKVEA | Q19: 253.0 | R19: MNFLLSTLEVAKMATDDYVGFTFFIGSMAMMAASAFFFLSLSQFDNKWRTSVLVSGLITFIAAVHYFYMRDYYAATDSSPTFFRYVDWTLTVPLMCVEFYLILKVAGAKLGLMWKLIFWSVVMLVTGYFGEVIALGNPTMQWVWGLVSGIAYFIIVYMIWFGEAKKLATSAGGAVLKAHNILCWFVLVGWAIYPLGYILGTEGGLFGLQLVEDPKAAQEAMDVVYNIGDAINKIGFGLVIYSLAVTSSKKVEA | U19: Nonlabens dokdonensis Rhodopsin-1 | V19: Nonlabens_dokdonensis_Rhodopsin_1 | W19: O0c174de93 | X19: FALSE | Y19: NdR1 | Z19: NdR1 | AA19: Proton pump | AB19: Nonlabens_dokdonensis_Rhodopsin_1_Nonlabens dokdonensis
A20: 19 | B20: include | C20: NdR2 | E20: Nonlabens dokdonensis | F20: Bacteria | G20: outward sodium pump | H20: outward sodium pump | L20: 10.1016/j.jphotobiol.2017.05.004 | M20: MIQDLGNSNFENYVGATDGFSEMAYQMTSHVLTLGYAVMFAGLLYFILTIKNVDKKYRMSNILSAVVMVSAALLLYAQAGNWTESFAFDAERGKYFLVEGGDLFNNGYRYLNWLIDVPMLLFQILFVVQLTKSKLSSVRNQFWFSGAMMIITGYIGQYYEVTDLSAFFIWGAISTVFFFHILWLMNKVIKEGKVGIPKKGQKILSNIWILFLVSWFLYPGAYLMPHLGGIEGFLFNESGVVGRQITYTIADVCSKVIYGVLLGNLALVLSKNKEMIETA | Q20: 279.0 | R20: MIQDLGNSNFENYVGATDGFSEMAYQMTSHVLTLGYAVMFAGLLYFILTIKNVDKKYRMSNILSAVVMVSAALLLYAQAGNWTESFAFDAERGKYFLVEGGDLFNNGYRYLNWLIDVPMLLFQILFVVQLTKSKLSSVRNQFWFSGAMMIITGYIGQYYEVTDLSAFFIWGAISTVFFFHILWLMNKVIKEGKVGIPKKGQKILSNIWILFLVSWFLYPGAYLMPHLGGIEGFLFNESGVVGRQITYTIADVCSKVIYGVLLGNLALVLSKNKEMIETA | U20: Nonlabens dokdonensis Rhodopsin-2 | V20: Nonlabens_dokdonensis_Rhodopsin_2 | W20: O82bd83f12 | X20: FALSE | Y20: NdR2 | Z20: NdR2 | AA20: Proton pump | AB20: Nonlabens_dokdonensis_Rhodopsin_2_Nonlabens dokdonensis
